Workbook

Sheet Monthly
A1: ตารางที่ 9 จำนวนผู้บรรจุงานจำแนกตามประเภทอาชีพ
A2: หน่วย : คน
A4: รหัส | B4: ประเภทอาชีพ | C4: ม.ค. 2557 | D4: ก.พ. 2557 | E4: มี.ค. 2557 | F4: เม.ย. 2557 | G4: พ.ค. 2557 | H4: มิ.ย. 2557 | I4: ก.ค. 2557 | J4: ส.ค. 2557 | K4: ก.ย. 2557 | L4: ต.ค. 2557 | M4: พ.ย. 2557 | N4: ธ.ค. 2557 | O4: ม.ค. 2558 | P4: ก.พ. 2558 | Q4: มี.ค. 2558 | R4: เม.ย. 2558 | S4: พ.ค. 2558 | T4: มิ.ย. 2558 | U4: ก.ค. 2558 | V4: ส.ค. 2558 | W4: ก.ย. 2558 | X4: ต.ค. 2558 | Y4: พ.ย. 2558 | Z4: ธ.ค. 2558 | AA4: ม.ค. 2559 | AB4: ก.พ. 2559 | AC4: มี.ค. 2559 | AD4: เม.ย. 2559 | AE4: พ.ค. 2559 | AF4: มิ.ย. 2559 | AG4: ก.ค. 2559 | AH4: ส.ค. 2559 | AI4: ก.ย. 2559 | AJ4: ต.ค. 2559 | AK4: พ.ย. 2559 | AL4: ธ.ค. 2559 | AM4: ม.ค. 2560 | AN4: ก.พ. 2560 | AO4: มี.ค. 2560 | AP4: เม.ย. 2560 | AQ4: พ.ค. 2560 | AR4: มิ.ย. 2560 | AS4: ก.ค. 2560 | AT4: ส.ค. 2560 | AU4: ก.ย. 2560 | AV4: ต.ค. 2560 | AW4: พ.ย. 2560 | AX4: ธ.ค. 2560 | AY4: ม.ค. 2561 | AZ4: ก.พ. 2561 | BA4: มี.ค. 2561 | BB4: เม.ย. 2561 | BC4: พ.ค. 2561 | BD4: มิ.ย. 2561 | BE4: ก.ค. 2561 | BF4: ส.ค. 2561 | BG4: ก.ย. 2561 | BH4: ต.ค. 2561 | BI4: พ.ย. 2561 | BJ4: ธ.ค. 2561 | BK4: ม.ค. 2562 | BL4: ก.พ. 2562 | BM4: มี.ค. 2562 | BN4: เม.ย. 2562 | BO4: พ.ค. 2562 | BP4: มิ.ย. 2562 | BQ4: ก.ค. 2562 | BR4: ส.ค. 2562 | BS4: ก.ย. 2562 | BT4: ต.ค. 2562 | BU4: พ.ย. 2562 | BV4: ธ.ค. 2562 | BW4: ม.ค. 2563 | BX4: ก.พ. 2563 | BY4: มี.ค. 2563 | BZ4: เม.ย. 2563 | CA4: พ.ค. 2563 | CB4: มิ.ย. 2563 | CC4: ก.ค. 2563 | CD4: ส.ค. 2563 | CE4: ก.ย. 2563 | CF4: ต.ค. 2563 | CG4: พ.ย. 2563 | CH4: ธ.ค.2563 | CI4: ม.ค. 2564 | CJ4: ก.พ. 2564 | CK4: มี.ค. 2564 | CL4: เม.ย. 2564 | CM4: พ.ค.2564 | CN4: มิ.ย. 2564 | CO4: ก.ค. 2564 | CP4: ส.ค. 2564 | CQ4: ก.ย. 2564 | CR4: ต.ค. 2564 | CS4: พ.ย. 2564 | CT4: ธ.ค.2564 | CU4: ม.ค. 2565 | CV4: ก.พ. 2565 | CW4: มี.ค. 2565 | CX4: เม.ย. 2565 | CY4: พ.ค.2565 | CZ4: มิ.ย. 2565 | DA4: ก.ค. 2565 | DB4: ส.ค. 2565 | DC4: ก.ย. 2565 | DD4: ต.ค. 2565 | DE4: พ.ย. 2565 | DF4: ธ.ค.2565 | DG4: ม.ค. 2566 | DH4: ก.พ. 2566 | DI4: มี.ค. 2566 | DJ4: เม.ย. 2566 | DK4: พ.ค.2566 | DL4: มิ.ย. 2566 | DM4: ก.ค. 2566 | DN4: ส.ค. 2566 | DO4: ก.ย. 2566 | DP4: ต.ค. 2566 | DQ4: พ.ย. 2566 | DR4: ธ.ค.2566 | DS4: ม.ค. 2567 | DT4: ก.พ.2567 | DU4: มี.ค. 2567 | DV4: เม.ย. 2567 | DW4: พ.ค. 2567 | DX4: มิ.ย. 2567 | DY4: ก.ค. 2567 | DZ4: ส.ค. 2567 | EA4: ก.ย. 2567 | EB4: ต.ค. 2567 | EC4: พ.ย. 2567 | ED4: ธ.ค. 2567 | EE4: ม.ค. 2568 | EF4: ก.พ.2568 | EG4: มี.ค.2568 | EH4: เม.ย.2568 | EI4: พ.ค.2568 | EJ4: มิ.ย.2568 | EK4: ก.ค.2568 | EL4: ส.ค.2568 | EM4: ก.ย.2568 | EN4: ต.ค.2568 | EO4: พ.ย.2568 | EP4: ธ.ค.2568 | EQ4: ม.ค.2569 | ER4: ก.พ.2569 | ES4: มี.ค.2569 | ET4: เม.ย.69 | EU4: พ.ค.69 | EV4: มิ.ย.69 | EW4: ก.ค.69 | EX4: ส.ค.69
B5: รวม | C5: =SUM(C6:C17) -> 22260 | D5: =SUM(D6:D17) -> 26286 | E5: =SUM(E6:E17) -> 30806 | F5: =SUM(F6:F17) -> 33290 | G5: =SUM(G6:G17) -> 27256 | H5: =SUM(H6:H17) -> 37833 | I5: =SUM(I6:I17) -> 35369 | J5: =SUM(J6:J17) -> 44380 | ... EX5: =SUM(EX6:EX17) -> 10068
A6: ="1" -> 1 | B6: ผู้บัญญัติกฎหมาย ข้าราชการระดับอาวุโส, ผู้จัดการ | C6: 373 | D6: 531 | E6: 555 | F6: 558 | G6: 499 | H6: 496 | I6: 623 | J6: 627 | K6: 755 | L6: 393 | M6: 521 | N6: 476 | O6: 557 | P6: 545 | Q6: 538 | R6: 400 | S6: 557 | T6: 1007 | U6: 770 | V6: 532 | W6: 559 | X6: 691 | Y6: 638 | Z6: 574 | AA6: 644 | AB6: 633 | AC6: 567 | AD6: 642 | AE6: 568 | AF6: 588 | AG6: 566 | AH6: 581 | AI6: 476 | AJ6: 373 | AK6: 432 | AL6: 302 | AM6: 388 | AN6: 426 | AO6: 524 | AP6: 431 | AQ6: 499 | AR6: 621 | AS6: 538 | AT6: 568 | AU6: 698 | AV6: 341 | AW6: 519 | AX6: 417 | AY6: 498 | AZ6: 494 | BA6: 597 | BB6: 499 | BC6: 473 | BD6: 519 | BE6: 384 | BF6: 400 | BG6: 505 | BH6: 499 | BI6: 375 | BJ6: 353 | BK6: 455 | BL6: 477 | BM6: 507 | BN6: 420 | BO6: 617 | BP6: 502 | BQ6: 526 | BR6: 653 | BS6: 387 | BT6: 371 | BU6: 373 | BV6: 367 | BW6: 272 | BX6: 491 | BY6: 584 | BZ6: 740 | CA6: 732 | CB6: 561 | CC6: 643 | CD6: 699 | CE6: 486 | CF6: 344 | CG6: 1019 | CH6: 874 | CI6: 536 | CJ6: 841 | CK6: 642 | CL6: 616 | CM6: 637 | CN6: 695 | CO6: 625 | CP6: 699 | CQ6: 747 | CR6: 279 | CS6: 255 | CT6: 318 | CU6: 352 | CV6: 560 | CW6: 964 | CX6: 548 | CY6: 810 | CZ6: 825 | DA6: 560 | DB6: 782 | DC6: 721 | DD6: 310 | DE6: 429 | DF6: 400 | DG6: 307 | DH6: 427 | DI6: 316 | DJ6: 345 | DK6: 368 | DL6: 367 | DM6: 398 | DN6: 441 | DO6: 252 | DP6: 325 | DQ6: 338 | DR6: 315 | DS6: 389 | DT6: 357 | DU6: 233 | DV6: 205 | DW6: 160 | DX6: 254 | DY6: 201 | DZ6: 207 | EA6: 126 | EB6: 197 | EC6: 237 | ED6: 241 | EE6: 150 | EF6: 148 | EG6: 171 | EH6: 184 | EI6: 165 | EJ6: 195 | EK6: 207 | EL6: 144 | EM6: 87 | EN6: 321 | EO6: 219 | EP6: 165 | EQ6: 126 | ER6: 323 | ES6: 119 | ET6: 177 | EU6: 285 | EV6: 258 | EW6: 157 | EX6: 145
A7: ="2" -> 2 | B7: ผู้ประกอบวิชาชีพด้านต่าง ๆ | C7: 998 | D7: 1191 | E7: 1464 | F7: 1591 | G7: 1222 | H7: 1982 | I7: 1671 | J7: 2005 | K7: 2421 | L7: 894 | M7: 1536 | N7: 1148 | O7: 1252 | P7: 1717 | Q7: 1575 | R7: 1532 | S7: 1971 | T7: 2323 | U7: 2687 | V7: 1764 | W7: 1840 | X7: 1145 | Y7: 1753 | Z7: 1318 | AA7: 1269 | AB7: 1309 | AC7: 1400 | AD7: 1212 | AE7: 1610 | AF7: 1797 | AG7: 1173 | AH7: 1386 | AI7: 1018 | AJ7: 808 | AK7: 824 | AL7: 748 | AM7: 901 | AN7: 1023 | AO7: 909 | AP7: 738 | AQ7: 1130 | AR7: 1837 | AS7: 1517 | AT7: 1626 | AU7: 1335 | AV7: 690 | AW7: 771 | AX7: 709 | AY7: 953 | AZ7: 998 | BA7: 1039 | BB7: 856 | BC7: 1025 | BD7: 738 | BE7: 769 | BF7: 793 | BG7: 1018 | BH7: 649 | BI7: 630 | BJ7: 735 | BK7: 768 | BL7: 871 | BM7: 837 | BN7: 882 | BO7: 1024 | BP7: 947 | BQ7: 1235 | BR7: 1094 | BS7: 766 | BT7: 813 | BU7: 712 | BV7: 685 | BW7: 1010 | BX7: 842 | BY7: 779 | BZ7: 361 | CA7: 450 | CB7: 444 | CC7: 901 | CD7: 679 | CE7: 578 | CF7: 440 | CG7: 1169 | CH7: 972 | CI7: 646 | CJ7: 881 | CK7: 731 | CL7: 390 | CM7: 696 | CN7: 782 | CO7: 542 | CP7: 823 | CQ7: 974 | CR7: 336 | CS7: 330 | CT7: 273 | CU7: 351 | CV7: 606 | CW7: 666 | CX7: 570 | CY7: 612 | CZ7: 920 | DA7: 509 | DB7: 645 | DC7: 724 | DD7: 385 | DE7: 551 | DF7: 493 | DG7: 390 | DH7: 355 | DI7: 514 | DJ7: 383 | DK7: 341 | DL7: 465 | DM7: 487 | DN7: 462 | DO7: 442 | DP7: 330 | DQ7: 331 | DR7: 245 | DS7: 296 | DT7: 411 | DU7: 338 | DV7: 449 | DW7: 387 | DX7: 445 | DY7: 479 | DZ7: 426 | EA7: 433 | EB7: 275 | EC7: 479 | ED7: 408 | EE7: 378 | EF7: 424 | EG7: 436 | EH7: 495 | EI7: 481 | EJ7: 519 | EK7: 471 | EL7: 333 | EM7: 256 | EN7: 297 | EO7: 403 | EP7: 383 | EQ7: 288 | ER7: 507 | ES7: 616 | ET7: 372 | EU7: 444 | EV7: 453 | EW7: 368 | EX7: 223
A8: ="3" -> 3 | B8: ช่างเทคนิคและผู้ปฏิบัติงานที่เกี่ยวข้อง | C8: 2325 | D8: 2908 | E8: 3525 | F8: 3500 | G8: 3111 | H8: 4198 | I8: 3873 | J8: 4946 | K8: 5464 | L8: 2477 | M8: 3432 | N8: 3285 | O8: 3304 | P8: 4198 | Q8: 3471 | R8: 3391 | S8: 3815 | T8: 4618 | U8: 4837 | V8: 3672 | W8: 3909 | X8: 2783 | Y8: 3764 | Z8: 3541 | AA8: 3389 | AB8: 3372 | AC8: 3385 | AD8: 3407 | AE8: 3724 | AF8: 3980 | AG8: 2894 | AH8: 2878 | AI8: 3036 | AJ8: 1563 | AK8: 2206 | AL8: 1976 | AM8: 2058 | AN8: 2619 | AO8: 2862 | AP8: 2389 | AQ8: 2683 | AR8: 4206 | AS8: 3717 | AT8: 3143 | AU8: 3275 | AV8: 1554 | AW8: 2103 | AX8: 1822 | AY8: 2585 | AZ8: 2939 | BA8: 2908 | BB8: 2918 | BC8: 3910 | BD8: 2451 | BE8: 1838 | BF8: 2276 | BG8: 2262 | BH8: 1610 | BI8: 1858 | BJ8: 2061 | BK8: 2556 | BL8: 3120 | BM8: 4125 | BN8: 4364 | BO8: 4516 | BP8: 2646 | BQ8: 2587 | BR8: 3027 | BS8: 1967 | BT8: 1670 | BU8: 1790 | BV8: 1827 | BW8: 1839 | BX8: 2180 | BY8: 2664 | BZ8: 1792 | CA8: 3057 | CB8: 4586 | CC8: 4270 | CD8: 4713 | CE8: 2771 | CF8: 2239 | CG8: 4711 | CH8: 3686 | CI8: 3156 | CJ8: 3218 | CK8: 2968 | CL8: 2737 | CM8: 3355 | CN8: 3668 | CO8: 4025 | CP8: 3777 | CQ8: 3482 | CR8: 1342 | CS8: 1770 | CT8: 1788 | CU8: 1938 | CV8: 3610 | CW8: 3464 | CX8: 3059 | CY8: 3629 | CZ8: 3581 | DA8: 2997 | DB8: 3425 | DC8: 2422 | DD8: 1883 | DE8: 2342 | DF8: 2134 | DG8: 2264 | DH8: 2991 | DI8: 3153 | DJ8: 2613 | DK8: 2667 | DL8: 2917 | DM8: 2762 | DN8: 2387 | DO8: 2218 | DP8: 2281 | DQ8: 2488 | DR8: 2533 | DS8: 2699 | DT8: 2996 | DU8: 2691 | DV8: 2756 | DW8: 2580 | DX8: 3431 | DY8: 2703 | DZ8: 2589 | EA8: 2292 | EB8: 2322 | EC8: 2881 | ED8: 2727 | EE8: 2546 | EF8: 2945 | EG8: 2921 | EH8: 2293 | EI8: 2786 | EJ8: 3305 | EK8: 2733 | EL8: 2163 | EM8: 1701 | EN8: 2131 | EO8: 2851 | EP8: 2935 | EQ8: 2207 | ER8: 3460 | ES8: 2917 | ET8: 2445 | EU8: 2490 | EV8: 2674 | EW8: 2031 | EX8: 1761
A9: ="4" -> 4 | B9: เสมียน เจ้าหน้าที่ | C9: 3864 | D9: 5054 | E9: 5737 | F9: 6120 | G9: 4790 | H9: 7348 | I9: 6672 | J9: 6981 | K9: 9084 | L9: 3986 | M9: 5718 | N9: 5255 | O9: 4967 | P9: 6096 | Q9: 6310 | R9: 5194 | S9: 6239 | T9: 8191 | U9: 7901 | V9: 6268 | W9: 5771 | X9: 4605 | Y9: 6783 | Z9: 5243 | AA9: 5426 | AB9: 5326 | AC9: 5493 | AD9: 5140 | AE9: 5476 | AF9: 5738 | AG9: 4365 | AH9: 4130 | AI9: 3593 | AJ9: 2494 | AK9: 3848 | AL9: 3073 | AM9: 3586 | AN9: 4568 | AO9: 4572 | AP9: 3558 | AQ9: 4775 | AR9: 6792 | AS9: 6147 | AT9: 4881 | AU9: 4979 | AV9: 2962 | AW9: 3849 | AX9: 3399 | AY9: 4432 | AZ9: 4188 | BA9: 4256 | BB9: 4648 | BC9: 5276 | BD9: 4116 | BE9: 3571 | BF9: 3473 | BG9: 3234 | BH9: 3125 | BI9: 3622 | BJ9: 3764 | BK9: 3663 | BL9: 4019 | BM9: 5295 | BN9: 5629 | BO9: 5655 | BP9: 4927 | BQ9: 4491 | BR9: 4842 | BS9: 3391 | BT9: 2760 | BU9: 3053 | BV9: 2977 | BW9: 2780 | BX9: 3197 | BY9: 3523 | BZ9: 1948 | CA9: 2618 | CB9: 3872 | CC9: 3824 | CD9: 3731 | CE9: 3558 | CF9: 1928 | CG9: 3820 | CH9: 3790 | CI9: 3028 | CJ9: 2612 | CK9: 2625 | CL9: 2388 | CM9: 2659 | CN9: 3526 | CO9: 2554 | CP9: 2794 | CQ9: 2497 | CR9: 1300 | CS9: 1651 | CT9: 1788 | CU9: 1744 | CV9: 3024 | CW9: 2770 | CX9: 2984 | CY9: 4453 | CZ9: 3788 | DA9: 3250 | DB9: 4178 | DC9: 3024 | DD9: 1500 | DE9: 2632 | DF9: 2205 | DG9: 2004 | DH9: 2321 | DI9: 2374 | DJ9: 2056 | DK9: 1945 | DL9: 2472 | DM9: 2739 | DN9: 1788 | DO9: 1331 | DP9: 1442 | DQ9: 1803 | DR9: 1950 | DS9: 1835 | DT9: 2094 | DU9: 2299 | DV9: 2058 | DW9: 1959 | DX9: 2778 | DY9: 2524 | DZ9: 2427 | EA9: 1869 | EB9: 1644 | EC9: 2627 | ED9: 2035 | EE9: 2018 | EF9: 2291 | EG9: 2400 | EH9: 2244 | EI9: 2298 | EJ9: 2741 | EK9: 2228 | EL9: 1784 | EM9: 1166 | EN9: 1872 | EO9: 2366 | EP9: 2401 | EQ9: 1871 | ER9: 2484 | ES9: 2500 | ET9: 2226 | EU9: 2519 | EV9: 2310 | EW9: 2055 | EX9: 1533
A10: ="5" -> 5 | B10: พนักงานบริการ พนักงานขายในร้านค้าและตลาด | C10: 3852 | D10: 5050 | E10: 5989 | F10: 5866 | G10: 5151 | H10: 6729 | I10: 7224 | J10: 7588 | K10: 8859 | L10: 4482 | M10: 6642 | N10: 6622 | O10: 6193 | P10: 7549 | Q10: 7250 | R10: 6313 | S10: 7060 | T10: 8410 | U10: 8128 | V10: 6876 | W10: 6213 | X10: 5058 | Y10: 6614 | Z10: 6059 | AA10: 6083 | AB10: 5747 | AC10: 5974 | AD10: 5431 | AE10: 6216 | AF10: 6606 | AG10: 4550 | AH10: 4943 | AI10: 4924 | AJ10: 3355 | AK10: 3725 | AL10: 3800 | AM10: 4467 | AN10: 4360 | AO10: 5094 | AP10: 4052 | AQ10: 5085 | AR10: 8139 | AS10: 7435 | AT10: 6549 | AU10: 6453 | AV10: 3154 | AW10: 3890 | AX10: 4138 | AY10: 5241 | AZ10: 5724 | BA10: 5704 | BB10: 5947 | BC10: 4916 | BD10: 3831 | BE10: 3661 | BF10: 4511 | BG10: 3388 | BH10: 3670 | BI10: 3983 | BJ10: 4296 | BK10: 4887 | BL10: 4961 | BM10: 6423 | BN10: 6697 | BO10: 6677 | BP10: 4593 | BQ10: 4890 | BR10: 5409 | BS10: 3818 | BT10: 3455 | BU10: 3699 | BV10: 3952 | BW10: 3765 | BX10: 4201 | BY10: 4338 | BZ10: 1056 | CA10: 1895 | CB10: 2867 | CC10: 3374 | CD10: 3615 | CE10: 3151 | CF10: 1930 | CG10: 5020 | CH10: 3598 | CI10: 2568 | CJ10: 2217 | CK10: 1846 | CL10: 1995 | CM10: 2274 | CN10: 2290 | CO10: 1691 | CP10: 2215 | CQ10: 1648 | CR10: 910 | CS10: 1076 | CT10: 1588 | CU10: 1981 | CV10: 2239 | CW10: 3280 | CX10: 2574 | CY10: 3338 | CZ10: 3239 | DA10: 2781 | DB10: 2999 | DC10: 2792 | DD10: 1395 | DE10: 1928 | DF10: 2166 | DG10: 2173 | DH10: 2654 | DI10: 2321 | DJ10: 1835 | DK10: 2000 | DL10: 1905 | DM10: 2109 | DN10: 1698 | DO10: 1281 | DP10: 1434 | DQ10: 1823 | DR10: 1562 | DS10: 1934 | DT10: 1785 | DU10: 2041 | DV10: 2263 | DW10: 2023 | DX10: 2310 | DY10: 2224 | DZ10: 1758 | EA10: 1560 | EB10: 1673 | EC10: 2099 | ED10: 2248 | EE10: 1902 | EF10: 2056 | EG10: 2244 | EH10: 2180 | EI10: 1991 | EJ10: 2368 | EK10: 1958 | EL10: 1248 | EM10: 1320 | EN10: 1530 | EO10: 1995 | EP10: 2321 | EQ10: 2612 | ER10: 2434 | ES10: 2282 | ET10: 2399 | EU10: 2154 | EV10: 1890 | EW10: 1587 | EX10: 1384
A11: ="6" -> 6 | B11: ผู้ปฏิบัติงานฝีมือด้านการเกษตรและประมง (แปรรูปขั้นพื้นฐาน) | C11: 152 | D11: 55 | E11: 53 | F11: 50 | G11: 63 | H11: 94 | I11: 89 | J11: 192 | K11: 77 | L11: 25 | M11: 66 | N11: 190 | O11: 95 | P11: 204 | Q11: 52 | R11: 106 | S11: 77 | T11: 86 | U11: 135 | V11: 36 | W11: 64 | X11: 65 | Y11: 184 | Z11: 64 | AA11: 102 | AB11: 72 | AC11: 56 | AD11: 56 | AE11: 85 | AF11: 84 | AG11: 65 | AH11: 34 | AI11: 80 | AJ11: 19 | AK11: 61 | AL11: 36 | AM11: 47 | AN11: 49 | AO11: 50 | AP11: 57 | AQ11: 55 | AR11: 98 | AS11: 126 | AT11: 82 | AU11: 174 | AV11: 21 | AW11: 59 | AX11: 96 | AY11: 50 | AZ11: 99 | BA11: 64 | BB11: 31 | BC11: 81 | BD11: 104 | BE11: 42 | BF11: 48 | BG11: 46 | BH11: 45 | BI11: 52 | BJ11: 47 | BK11: 24 | BL11: 62 | BM11: 25 | BN11: 49 | BO11: 36 | BP11: 49 | BQ11: 34 | BR11: 205 | BS11: 23 | BT11: 27 | BU11: 103 | BV11: 20 | BW11: 22 | BX11: 49 | BY11: 29 | BZ11: 13 | CA11: 46 | CB11: 19 | CC11: 7 | CD11: 41 | CE11: 43 | CF11: 18 | CG11: 142 | CH11: 205 | CI11: 46 | CJ11: 53 | CK11: 40 | CL11: 36 | CM11: 20 | CN11: 15 | CO11: 20 | CP11: 24 | CQ11: 12 | CR11: 17 | CS11: 2 | CT11: 73 | CU11: 24 | CV11: 38 | CW11: 134 | CX11: 52 | CY11: 83 | CZ11: 30 | DA11: 25 | DB11: 16 | DC11: 39 | DD11: 24 | DE11: 47 | DF11: 27 | DG11: 37 | DH11: 33 | DI11: 27 | DJ11: 16 | DK11: 15 | DL11: 65 | DM11: 18 | DN11: 11 | DO11: 13 | DP11: 13 | DQ11: 13 | DR11: 32 | DS11: 19 | DT11: 31 | DU11: 12 | DV11: 21 | DW11: 37 | DX11: 11 | DY11: 8 | DZ11: 112 | EA11: 9 | EB11: 19 | EC11: 97 | ED11: 95 | EE11: 27 | EF11: 20 | EG11: 67 | EH11: 39 | EI11: 12 | EJ11: 16 | EK11: 28 | EL11: 19 | EM11: 14 | EN11: 17 | EO11: 34 | EP11: 4 | EQ11: 21 | ER11: 32 | ES11: 34 | ET11: 5 | EU11: 24 | EV11: 13 | EW11: 17 | EX11: 4
A12: ="7" -> 7 | B12: ผู้ปฏิบัติงานโดยใช้ฝีมือในธุรกิจต่าง ๆ | C12: 1228 | D12: 1377 | E12: 1444 | F12: 1648 | G12: 1698 | H12: 1854 | I12: 1954 | J12: 1865 | K12: 2782 | L12: 1105 | M12: 1690 | N12: 1407 | O12: 1368 | P12: 2023 | Q12: 1359 | R12: 1664 | S12: 1461 | T12: 2267 | U12: 2229 | V12: 2128 | W12: 1769 | X12: 1406 | Y12: 1669 | Z12: 1426 | AA12: 1436 | AB12: 1433 | AC12: 1689 | AD12: 1348 | AE12: 1492 | AF12: 1509 | AG12: 1263 | AH12: 1374 | AI12: 1277 | AJ12: 716 | AK12: 1004 | AL12: 907 | AM12: 852 | AN12: 987 | AO12: 1033 | AP12: 952 | AQ12: 1328 | AR12: 1480 | AS12: 1457 | AT12: 1179 | AU12: 1311 | AV12: 692 | AW12: 955 | AX12: 990 | AY12: 1068 | AZ12: 1006 | BA12: 916 | BB12: 1174 | BC12: 897 | BD12: 944 | BE12: 805 | BF12: 914 | BG12: 710 | BH12: 754 | BI12: 941 | BJ12: 750 | BK12: 861 | BL12: 1079 | BM12: 1204 | BN12: 1163 | BO12: 1339 | BP12: 1043 | BQ12: 856 | BR12: 1175 | BS12: 822 | BT12: 766 | BU12: 955 | BV12: 856 | BW12: 797 | BX12: 975 | BY12: 1106 | BZ12: 2005 | CA12: 2004 | CB12: 2110 | CC12: 2720 | CD12: 1282 | CE12: 611 | CF12: 375 | CG12: 1326 | CH12: 861 | CI12: 389 | CJ12: 384 | CK12: 433 | CL12: 323 | CM12: 573 | CN12: 713 | CO12: 640 | CP12: 1101 | CQ12: 618 | CR12: 266 | CS12: 338 | CT12: 280 | CU12: 389 | CV12: 820 | CW12: 382 | CX12: 843 | CY12: 1260 | CZ12: 770 | DA12: 957 | DB12: 648 | DC12: 866 | DD12: 329 | DE12: 498 | DF12: 612 | DG12: 619 | DH12: 801 | DI12: 602 | DJ12: 822 | DK12: 553 | DL12: 410 | DM12: 727 | DN12: 451 | DO12: 417 | DP12: 342 | DQ12: 476 | DR12: 439 | DS12: 494 | DT12: 564 | DU12: 547 | DV12: 522 | DW12: 545 | DX12: 638 | DY12: 531 | DZ12: 479 | EA12: 494 | EB12: 357 | EC12: 459 | ED12: 547 | EE12: 352 | EF12: 422 | EG12: 575 | EH12: 545 | EI12: 620 | EJ12: 540 | EK12: 480 | EL12: 497 | EM12: 334 | EN12: 307 | EO12: 503 | EP12: 547 | EQ12: 407 | ER12: 444 | ES12: 412 | ET12: 417 | EU12: 471 | EV12: 383 | EW12: 439 | EX12: 264
A13: ="8" -> 8 | B13: ผู้ปฏิบัติงานในโรงงาน ผู้ควบคุมเครื่องจักรและผู้ปฏิบัติงานด้านการประกอบ | C13: 1850 | D13: 1593 | E13: 2200 | F13: 2594 | G13: 1847 | H13: 1748 | I13: 2316 | J13: 3245 | K13: 3689 | L13: 1250 | M13: 1949 | N13: 1900 | O13: 2269 | P13: 1921 | Q13: 2027 | R13: 1465 | S13: 1857 | T13: 3365 | U13: 3115 | V13: 3274 | W13: 2066 | X13: 1684 | Y13: 2206 | Z13: 1789 | AA13: 2689 | AB13: 1754 | AC13: 2423 | AD13: 1432 | AE13: 1779 | AF13: 1543 | AG13: 1486 | AH13: 1419 | AI13: 1901 | AJ13: 922 | AK13: 966 | AL13: 1147 | AM13: 1247 | AN13: 1371 | AO13: 1441 | AP13: 1120 | AQ13: 1638 | AR13: 1876 | AS13: 2114 | AT13: 1205 | AU13: 1682 | AV13: 822 | AW13: 988 | AX13: 1117 | AY13: 1705 | AZ13: 1156 | BA13: 1139 | BB13: 992 | BC13: 1086 | BD13: 1806 | BE13: 1010 | BF13: 1652 | BG13: 932 | BH13: 814 | BI13: 990 | BJ13: 1264 | BK13: 1586 | BL13: 1221 | BM13: 1655 | BN13: 1464 | BO13: 2008 | BP13: 1267 | BQ13: 1327 | BR13: 1567 | BS13: 1101 | BT13: 875 | BU13: 962 | BV13: 1128 | BW13: 1062 | BX13: 1361 | BY13: 1060 | BZ13: 464 | CA13: 624 | CB13: 956 | CC13: 801 | CD13: 1167 | CE13: 730 | CF13: 565 | CG13: 1286 | CH13: 1118 | CI13: 746 | CJ13: 821 | CK13: 725 | CL13: 581 | CM13: 685 | CN13: 979 | CO13: 506 | CP13: 797 | CQ13: 752 | CR13: 348 | CS13: 317 | CT13: 410 | CU13: 874 | CV13: 886 | CW13: 1865 | CX13: 1200 | CY13: 907 | CZ13: 1264 | DA13: 1138 | DB13: 1156 | DC13: 919 | DD13: 623 | DE13: 891 | DF13: 1234 | DG13: 636 | DH13: 978 | DI13: 1175 | DJ13: 1044 | DK13: 710 | DL13: 557 | DM13: 616 | DN13: 503 | DO13: 429 | DP13: 591 | DQ13: 745 | DR13: 543 | DS13: 892 | DT13: 798 | DU13: 829 | DV13: 676 | DW13: 814 | DX13: 1097 | DY13: 845 | DZ13: 815 | EA13: 534 | EB13: 713 | EC13: 743 | ED13: 760 | EE13: 854 | EF13: 795 | EG13: 797 | EH13: 657 | EI13: 685 | EJ13: 792 | EK13: 723 | EL13: 590 | EM13: 506 | EN13: 759 | EO13: 954 | EP13: 910 | EQ13: 500 | ER13: 496 | ES13: 552 | ET13: 614 | EU13: 503 | EV13: 442 | EW13: 481 | EX13: 391
A14: ="9" -> 9 | B14: อาชีพงานพื้นฐาน | C14: 7614 | D14: 8522 | E14: 9834 | F14: 11282 | G14: 8874 | H14: 13381 | I14: 10942 | J14: 16931 | K14: 19993 | L14: 9070 | M14: 11376 | N14: 9769 | O14: 9654 | P14: 11079 | Q14: 11380 | R14: 11140 | S14: 12288 | T14: 15050 | U14: 18036 | V14: 12098 | W14: 13351 | X14: 9316 | Y14: 11960 | Z14: 10422 | AA14: 9911 | AB14: 10779 | AC14: 13846 | AD14: 12025 | AE14: 12637 | AF14: 11626 | AG14: 10764 | AH14: 10019 | AI14: 10209 | AJ14: 5652 | AK14: 7082 | AL14: 6458 | AM14: 8776 | AN14: 8204 | AO14: 9715 | AP14: 9466 | AQ14: 12471 | AR14: 13983 | AS14: 10958 | AT14: 9870 | AU14: 10134 | AV14: 6059 | AW14: 7944 | AX14: 6678 | AY14: 7702 | AZ14: 8076 | BA14: 8629 | BB14: 8830 | BC14: 10920 | BD14: 7463 | BE14: 6725 | BF14: 6643 | BG14: 8665 | BH14: 6062 | BI14: 5951 | BJ14: 6640 | BK14: 7877 | BL14: 9326 | BM14: 11119 | BN14: 13838 | BO14: 10588 | BP14: 8323 | BQ14: 8287 | BR14: 10152 | BS14: 6475 | BT14: 6248 | BU14: 7177 | BV14: 6608 | BW14: 6982 | BX14: 7491 | BY14: 9312 | BZ14: 3711 | CA14: 6183 | CB14: 9757 | CC14: 9071 | CD14: 11994 | CE14: 8329 | CF14: 7227 | CG14: 20216 | CH14: 15725 | CI14: 11772 | CJ14: 12888 | CK14: 10741 | CL14: 7926 | CM14: 10751 | CN14: 13009 | CO14: 10337 | CP14: 11477 | CQ14: 11348 | CR14: 4804 | CS14: 7156 | CT14: 7572 | CU14: 7328 | CV14: 11985 | CW14: 12376 | CX14: 10644 | CY14: 13295 | CZ14: 12293 | DA14: 9942 | DB14: 10905 | DC14: 11836 | DD14: 6409 | DE14: 8728 | DF14: 8493 | DG14: 8167 | DH14: 8273 | DI14: 8707 | DJ14: 7692 | DK14: 7390 | DL14: 7030 | DM14: 6823 | DN14: 6261 | DO14: 4806 | DP14: 5240 | DQ14: 5832 | DR14: 5696 | DS14: 6576 | DT14: 7472 | DU14: 6749 | DV14: 6696 | DW14: 7160 | DX14: 8297 | DY14: 9101 | DZ14: 7444 | EA14: 6469 | EB14: 6004 | EC14: 6733 | ED14: 6875 | EE14: 6741 | EF14: 7378 | EG14: 7417 | EH14: 7439 | EI14: 6943 | EJ14: 8584 | EK14: =2+6669 -> 6671 | EL14: =3+5507 -> 5510 | EM14: =1+3589 -> 3590 | EN14: =5+6306 -> 6311 | EO14: =2+7309 -> 7311 | EP14: 8569 | EQ14: 7032 | ER14: =10+7745 -> 7755 | ES14: 7946 | ET14: 7396 | EU14: 7335 | EV14: =2+6883 -> 6885 | EW14: 5757 | EX14: 4363
A15: 0 | B15: ทหาร | BZ15: 1
A16: ="T" -> T | B16: ผู้ฝึกงาน | C16: 4 | D16: 5 | E16: 5 | F16: 81 | G16: 1 | H16: 3 | I16: 5 | J16: 0 | K16: 20 | L16: 1 | M16: 1 | N16: 31 | O16: 19 | P16: 13 | Q16: 17 | R16: 36 | S16: 27 | T16: 20 | U16: 29 | V16: 1 | W16: 20 | X16: 5 | Y16: 22 | Z16: 15 | AA16: 7 | AB16: 11 | AC16: 3 | AD16: 18 | AE16: 2 | AF16: 75 | AG16: 0 | AH16: 3 | AI16: 1 | AJ16: 0 | AK16: 1 | AL16: 4 | AM16: 5 | AN16: 10 | AO16: 9 | AP16: 15 | AQ16: 6 | AR16: 4 | AS16: 2 | AT16: 14 | AU16: 1 | AV16: 0 | AW16: 1 | AX16: 0 | AY16: 40 | AZ16: 20 | BA16: 92 | BB16: 77 | BC16: 81 | BD16: 0 | BE16: 0 | BF16: 0 | BG16: 2 | BH16: 0 | BI16: 2 | BJ16: 15 | BK16: 22 | BL16: 197 | BM16: 504 | BN16: 51 | BO16: 79 | BP16: 14 | BQ16: 6 | BR16: 64 | BS16: 0 | BT16: 0 | BU16: 0 | BV16: 1 | BW16: 1 | BX16: 0 | BY16: 1 | CA16: 3 | CB16: 2 | CD16: 12
A17: X | B17: ผู้ปฏิบัติงานซึ่งมิอาจจัดประเภทได้ | C17: 0 | AY17: 0 | AZ17: 0 | BA17: 0 | BB17: 0 | BC17: 0 | BD17: 0 | BE17: 0 | BF17: 0 | BG17: 0 | BH17: 0 | BI17: 0 | BJ17: 0 | BK17: 0 | BL17: 0 | BM17: 0 | BN17: 0 | BO17: 0 | BP17: 0 | BQ17: 0 | BR17: 0 | BS17: 0 | BT17: 0 | BU17: 0 | BV17: 0 | BW17: 0 | BX17: 0 | BY17: 0 | BZ17: 0 | CA17: 1 | CE17: 1 | CG17: 1
A19: ที่มา : กรมการจัดหางาน
A20: รวบรวมโดย : กองบริหารข้อมูลตลาดแรงงาน
A21: หมายเหตุ : 1. เป็นข้อมูลผู้สมัครงานที่มาใช้บริการจัดหางานกับกรมการจัดหางานเท่านั้น
A22: 2. ข้อมูลจากระบบสารสนเทศการจัดหางานในประเทศ กรมการจัดหางาน

Sheet CSV
A1: จำนวนผู้บรรจุงานจำแนกตามประเภทอาชีพ
A2: Year | B2: Month | C2: Total | D2: ="1" -> 1 | E2: ="2" -> 2 | F2: ="3" -> 3 | G2: ="4" -> 4 | H2: ="5" -> 5 | I2: ="6" -> 6 | J2: ="7" -> 7 | K2: ="8" -> 8 | L2: ="9" -> 9 | M2: 0 | N2: ="T" -> T | O2: X
A3: 2014 | B3: Jan | C3: =SUM(D3:O3) -> 22260 | D3: 373 | E3: 998 | F3: 2325 | G3: 3864 | H3: 3852 | I3: 152 | J3: 1228 | K3: 1850 | L3: 7614 | N3: 4 | O3: 0
A4: 2014 | B4: Feb | C4: =SUM(D4:O4) -> 26286 | D4: 531 | E4: 1191 | F4: 2908 | G4: 5054 | H4: 5050 | I4: 55 | J4: 1377 | K4: 1593 | L4: 8522 | N4: 5
A5: 2014 | B5: Mar | C5: =SUM(D5:O5) -> 30806 | D5: 555 | E5: 1464 | F5: 3525 | G5: 5737 | H5: 5989 | I5: 53 | J5: 1444 | K5: 2200 | L5: 9834 | N5: 5
A6: 2014 | B6: Apr | C6: =SUM(D6:O6) -> 33290 | D6: 558 | E6: 1591 | F6: 3500 | G6: 6120 | H6: 5866 | I6: 50 | J6: 1648 | K6: 2594 | L6: 11282 | N6: 81
A7: 2014 | B7: May | C7: =SUM(D7:O7) -> 27256 | D7: 499 | E7: 1222 | F7: 3111 | G7: 4790 | H7: 5151 | I7: 63 | J7: 1698 | K7: 1847 | L7: 8874 | N7: 1
A8: 2014 | B8: Jun | C8: =SUM(D8:O8) -> 37833 | D8: 496 | E8: 1982 | F8: 4198 | G8: 7348 | H8: 6729 | I8: 94 | J8: 1854 | K8: 1748 | L8: 13381 | N8: 3
A9: 2014 | B9: Jul | C9: =SUM(D9:O9) -> 35369 | D9: 623 | E9: 1671 | F9: 3873 | G9: 6672 | H9: 7224 | I9: 89 | J9: 1954 | K9: 2316 | L9: 10942 | N9: 5
A10: 2014 | B10: Aug | C10: =SUM(D10:O10) -> 44380 | D10: 627 | E10: 2005 | F10: 4946 | G10: 6981 | H10: 7588 | I10: 192 | J10: 1865 | K10: 3245 | L10: 16931 | N10: 0
A11: 2014 | B11: Sep | C11: =SUM(D11:O11) -> 53144 | D11: 755 | E11: 2421 | F11: 5464 | G11: 9084 | H11: 8859 | I11: 77 | J11: 2782 | K11: 3689 | L11: 19993 | N11: 20
A12: 2014 | B12: Oct | C12: =SUM(D12:O12) -> 23683 | D12: 393 | E12: 894 | F12: 2477 | G12: 3986 | H12: 4482 | I12: 25 | J12: 1105 | K12: 1250 | L12: 9070 | N12: 1
A13: 2014 | B13: Nov | C13: =SUM(D13:O13) -> 32931 | D13: 521 | E13: 1536 | F13: 3432 | G13: 5718 | H13: 6642 | I13: 66 | J13: 1690 | K13: 1949 | L13: 11376 | N13: 1
A14: 2014 | B14: Dec | C14: =SUM(D14:O14) -> 30083 | D14: 476 | E14: 1148 | F14: 3285 | G14: 5255 | H14: 6622 | I14: 190 | J14: 1407 | K14: 1900 | L14: 9769 | N14: 31
A15: 2015 | B15: Jan | C15: =SUM(D15:O15) -> 29678 | D15: 557 | E15: 1252 | F15: 3304 | G15: 4967 | H15: 6193 | I15: 95 | J15: 1368 | K15: 2269 | L15: 9654 | N15: 19
... A50: 2017 | B50: Dec | C50: =SUM(D50:O50) -> 19366 | D50: 417 | E50: 709 | F50: 1822 | G50: 3399 | H50: 4138 | I50: 96 | J50: 990 | K50: 1117 | L50: 6678 | N50: 0
A51: 2018 | B51: Jan | C51: =SUM(D51:O51) -> 24274 | D51: 498 | E51: 953 | F51: 2585 | G51: 4432 | H51: 5241 | I51: 50 | J51: 1068 | K51: 1705 | L51: 7702 | N51: 40 | O51: 0
A52: 2018 | B52: Feb | C52: =SUM(D52:O52) -> 24700 | D52: 494 | E52: 998 | F52: 2939 | G52: 4188 | H52: 5724 | I52: 99 | J52: 1006 | K52: 1156 | L52: 8076 | N52: 20 | O52: 0
A53: 2018 | B53: Mar | C53: =SUM(D53:O53) -> 25344 | D53: 597 | E53: 1039 | F53: 2908 | G53: 4256 | H53: 5704 | I53: 64 | J53: 916 | K53: 1139 | L53: 8629 | N53: 92 | O53: 0
A54: 2018 | B54: Apr | C54: =SUM(D54:O54) -> 25972 | D54: 499 | E54: 856 | F54: 2918 | G54: 4648 | H54: 5947 | I54: 31 | J54: 1174 | K54: 992 | L54: 8830 | N54: 77 | O54: 0
A55: 2018 | B55: May | C55: =SUM(D55:O55) -> 28665 | D55: 473 | E55: 1025 | F55: 3910 | G55: 5276 | H55: 4916 | I55: 81 | J55: 897 | K55: 1086 | L55: 10920 | N55: 81 | O55: 0
A56: 2018 | B56: Jun | C56: =SUM(D56:O56) -> 21972 | D56: 519 | E56: 738 | F56: 2451 | G56: 4116 | H56: 3831 | I56: 104 | J56: 944 | K56: 1806 | L56: 7463 | N56: 0 | O56: 0
A57: 2018 | B57: Jul | C57: =SUM(D57:O57) -> 18805 | D57: 384 | E57: 769 | F57: 1838 | G57: 3571 | H57: 3661 | I57: 42 | J57: 805 | K57: 1010 | L57: 6725 | N57: 0 | O57: 0
A58: 2018 | B58: Aug | C58: =SUM(D58:O58) -> 20710 | D58: 400 | E58: 793 | F58: 2276 | G58: 3473 | H58: 4511 | I58: 48 | J58: 914 | K58: 1652 | L58: 6643 | N58: 0 | O58: 0
A59: 2018 | B59: Sep | C59: =SUM(D59:O59) -> 20762 | D59: 505 | E59: 1018 | F59: 2262 | G59: 3234 | H59: 3388 | I59: 46 | J59: 710 | K59: 932 | L59: 8665 | N59: 2 | O59: 0
A60: 2018 | B60: Oct | C60: =SUM(D60:O60) -> 17228 | D60: 499 | E60: 649 | F60: 1610 | G60: 3125 | H60: 3670 | I60: 45 | J60: 754 | K60: 814 | L60: 6062 | N60: 0 | O60: 0
A61: 2018 | B61: Nov | C61: =SUM(D61:O61) -> 18404 | D61: 375 | E61: 630 | F61: 1858 | G61: 3622 | H61: 3983 | I61: 52 | J61: 941 | K61: 990 | L61: 5951 | N61: 2 | O61: 0
A62: 2018 | B62: Dec | C62: =SUM(D62:O62) -> 19925 | D62: 353 | E62: 735 | F62: 2061 | G62: 3764 | H62: 4296 | I62: 47 | J62: 750 | K62: 1264 | L62: 6640 | N62: 15 | O62: 0
... A77: 2020 | B77: Mar | C77: =SUM(D77:O77) -> 23396 | D77: 584 | E77: 779 | F77: 2664 | G77: 3523 | H77: 4338 | I77: 29 | J77: 1106 | K77: 1060 | L77: 9312 | N77: 1 | O77: 0
A78: 2020 | B78: Apr | C78: =SUM(D78:O78) -> 12091 | D78: 740 | E78: 361 | F78: 1792 | G78: 1948 | H78: 1056 | I78: 13 | J78: 2005 | K78: 464 | L78: 3711 | M78: 1 | O78: 0
A79: 2020 | B79: May | C79: =SUM(D79:O79) -> 17613 | D79: 732 | E79: 450 | F79: 3057 | G79: 2618 | H79: 1895 | I79: 46 | J79: 2004 | K79: 624 | L79: 6183 | N79: 3 | O79: 1
A80: 2020 | B80: Jun | C80: =SUM(D80:O80) -> 25174 | D80: 561 | E80: 444 | F80: 4586 | G80: 3872 | H80: 2867 | I80: 19 | J80: 2110 | K80: 956 | L80: 9757 | N80: 2
A81: 2020 | B81: Jul | C81: =SUM(D81:O81) -> 25611 | D81: 643 | E81: 901 | F81: 4270 | G81: 3824 | H81: 3374 | I81: 7 | J81: 2720 | K81: 801 | L81: 9071
A82: 2020 | B82: Aug | C82: =SUM(D82:O82) -> 27933 | D82: 699 | E82: 679 | F82: 4713 | G82: 3731 | H82: 3615 | I82: 41 | J82: 1282 | K82: 1167 | L82: 11994 | N82: 12
A83: 2020 | B83: Sep | C83: =SUM(D83:O83) -> 20258 | D83: 486 | E83: 578 | F83: 2771 | G83: 3558 | H83: 3151 | I83: 43 | J83: 611 | K83: 730 | L83: 8329 | O83: 1
A84: 2020 | B84: Oct | C84: =SUM(D84:O84) -> 15066 | D84: 344 | E84: 440 | F84: 2239 | G84: 1928 | H84: 1930 | I84: 18 | J84: 375 | K84: 565 | L84: 7227
A85: 2020 | B85: Nov | C85: =SUM(D85:O85) -> 38710 | D85: 1019 | E85: 1169 | F85: 4711 | G85: 3820 | H85: 5020 | I85: 142 | J85: 1326 | K85: 1286 | L85: 20216 | O85: 1
A86: 2020 | B86: Dec | C86: =SUM(D86:O86) -> 30829 | D86: 874 | E86: 972 | F86: 3686 | G86: 3790 | H86: 3598 | I86: 205 | J86: 861 | K86: 1118 | L86: 15725
A87: 2021 | B87: Jan | C87: =SUM(D87:O87) -> 22887 | D87: 536 | E87: 646 | F87: 3156 | G87: 3028 | H87: 2568 | I87: 46 | J87: 389 | K87: 746 | L87: 11772
A88: 2021 | B88: Feb | C88: =SUM(D88:O88) -> 23915 | D88: 841 | E88: 881 | F88: 3218 | G88: 2612 | H88: 2217 | I88: 53 | J88: 384 | K88: 821 | L88: 12888
...

Sheet Data Dic
A1: จำนวนผู้บรรจุงานจำแนกตามประเภทอาชีพ
A2: ลำดับที่ | B2: ชื่อคอลัมภ์ | C2: ชนิดข้อมูล | D2: รายละเอียด
A3: 1 | B3: Year | C3: timestamp | D3: ปี ค.ศ.
A4: 2 | B4: Month | C4: timestamp | D4: เดือน
A5: 3 | B5: 1 | C5: numeric | D5: ผู้ปฏิบัติกฎหมาย ข้าราชการระดับอาวุโส ผู้จัดการ
A6: 4 | B6: 2 | C6: numeric | D6: ผู้ประกอบวิชาชีพต่าง ๆ
A7: 5 | B7: 3 | C7: numeric | D7: ช่างเทคนิคและผู้ปฏิบัติงานที่เกี่ยวข้อง
A8: 6 | B8: 4 | C8: numeric | D8: เสมียน เจ้าหน้าที่
A9: 7 | B9: 5 | C9: numeric | D9: พนักงานบริการ พนักงานขายในร้านค้าและตลาด
A10: 8 | B10: 6 | C10: numeric | D10: ผู้ปฏิบัติงานฝีมือด้านการเกษตร และประมง (แปรรูปขั้นพื้นฐาน)
A11: 9 | B11: 7 | C11: numeric | D11: ผู้ปฏิบัติงานโดยใช้ฝีมือในธุรกิจต่าง ๆ
A12: 10 | B12: 8 | C12: numeric | D12: ผู้ปฏิบัติงานในโรงงาน ผู้ควบคุมเรื่องจักรและผู้ปฏิบัติงานด้านการประกอบ
A13: 11 | B13: 9 | C13: numeric | D13: อาชีพงานพื้นฐาน
A14: 12 | B14: T | C14: numeric | D14: ผู้ฝึกงาน
A15: 13 | B15: X | C15: numeric | D15: ผู้ปฏิบัติงานซึ่งมิอาจจัดประเภท
A16: 14 | B16: 0 | C16: numeric | D16: ทหาร
