Workbook

Sheet Monthly
A1: ตารางที่ 15 จำนวนตำแหน่งงานจำแนกตามประเภทอาชีพ
A2: หน่วย : คน
A4: รหัส | B4: ประเภทอาชีพ | C4: ม.ค. 2557 | D4: ก.พ. 2557 | E4: มี.ค. 2557 | F4: เม.ย. 2557 | G4: พ.ค. 2557 | H4: มิ.ย. 2557 | I4: ก.ค. 2557 | J4: ส.ค. 2557 | K4: ก.ย. 2557 | L4: ต.ค. 2557 | M4: พ.ย. 2557 | N4: ธ.ค. 2557 | O4: ม.ค. 2558 | P4: ก.พ. 2558 | Q4: มี.ค. 2558 | R4: เม.ย. 2558 | S4: พ.ค. 2558 | T4: มิ.ย. 2558 | U4: ก.ค. 2558 | V4: ส.ค. 2558 | W4: ก.ย. 2558 | X4: ต.ค. 2558 | Y4: พ.ย. 2558 | Z4: ธ.ค. 2558 | AA4: ม.ค. 2559 | AB4: ก.พ. 2559 | AC4: มี.ค. 2559 | AD4: เม.ย. 2559 | AE4: พ.ค. 2559 | AF4: มิ.ย. 2559 | AG4: ก.ค. 2559 | AH4: ส.ค. 2559 | AI4: ก.ย. 2559 | AJ4: ต.ค. 2559 | AK4: พ.ย. 2559 | AL4: ธ.ค. 2559 | AM4: ม.ค. 2560 | AN4: ก.พ. 2560 | AO4: มี.ค. 2560 | AP4: เม.ย. 2560 | AQ4: พ.ค. 2560 | AR4: มิ.ย. 2560 | AS4: ก.ค. 2560 | AT4: ส.ค. 2560 | AU4: ก.ย. 2560 | AV4: ต.ค. 2560 | AW4: พ.ย. 2560 | AX4: ธ.ค. 2560 | AY4: ม.ค. 2561 | AZ4: ก.พ. 2561 | BA4: มี.ค. 2561 | BB4: เม.ย. 2561 | BC4: พ.ค. 2561 | BD4: มิ.ย. 2561 | BE4: ก.ค. 2561 | BF4: ส.ค. 2561 | BG4: ก.ย. 2561 | BH4: ต.ค. 2561 | BI4: พ.ย. 2561 | BJ4: ธ.ค. 2561 | BK4: ม.ค. 2562 | BL4: ก.พ. 2562 | BM4: มี.ค. 2562 | BN4: เม.ย. 2562 | BO4: พ.ค. 2562 | BP4: มิ.ย. 2562 | BQ4: ก.ค. 2562 | BR4: ส.ค. 2562 | BS4: ก.ย. 2562 | BT4: ต.ค. 2562 | BU4: พ.ย. 2562 | BV4: ธ.ค. 2562 | BW4: ม.ค. 2563 | BX4: ก.พ. 2563 | BY4: มี.ค. 2563 | BZ4: เม.ย. 2563 | CA4: พ.ค. 2563 | CB4: มิ.ย. 2563 | CC4: ก.ค. 2563 | CD4: ส.ค. 2563 | CE4: ก.ย. 2563 | CF4: ต.ค. 2563 | CG4: พ.ย. 2563 | CH4: ธ.ค.2563 | CI4: ม.ค. 2564 | CJ4: ก.พ. 2564 | CK4: มี.ค. 2564 | CL4: เม.ย. 2564 | CM4: พ.ค. 2564 | CN4: มิ.ย. 2564 | CO4: ก.ค. 2564 | CP4: ส.ค. 2564 | CQ4: ก.ย. 2564 | CR4: ต.ค. 2564 | CS4: พ.ย. 2564 | CT4: ธ.ค.2564 | CU4: ม.ค.2565 | CV4: ก.พ. 2565 | CW4: มี.ค. 2565 | CX4: เม.ย. 2565 | CY4: พ.ค. 2565 | CZ4: มิ.ย. 2565 | DA4: ก.ค. 2565 | DB4: ส.ค. 2565 | DC4: ก.ย. 2565 | DD4: ต.ค. 2565 | DE4: พ.ย. 2565 | DF4: ธ.ค.2565 | DG4: ม.ค.2566 | DH4: ก.พ. 2566 | DI4: มี.ค. 2566 | DJ4: เม.ย. 2566 | DK4: พ.ค. 2566 | DL4: มิ.ย. 2566 | DM4: ก.ค. 2566 | DN4: ส.ค. 2566 | DO4: ก.ย. 2566 | DP4: ต.ค. 2566 | DQ4: พ.ย. 2566 | DR4: ธ.ค.2566 | DS4: ม.ค. 2567 | DT4: ก.พ.2567 | DU4: มี.ค. 2567 | DV4: เม.ย. 2567 | DW4: พ.ค. 2567 | DX4: มิ.ย. 2567 | DY4: ก.ค. 2567 | DZ4: ส.ค. 2567 | EA4: ก.ย. 2567 | EB4: ต.ค. 2567 | EC4: พ.ย. 2567 | ED4: ธ.ค. 2567 | EE4: ม.ค. 2568 | EF4: ก.พ.2568 | EG4: มี.ค.2568 | EH4: เม.ย.2568 | EI4: พ.ค.2568 | EJ4: มิ.ย.2568 | EK4: ก.ค.2568 | EL4: ส.ค.2568 | EM4: ก.ย.2568 | EN4: ต.ค.2568 | EO4: พ.ย.2568 | EP4: ธ.ค.2568 | EQ4: ม.ค.2569 | ER4: ก.พ.2569 | ES4: มี.ค.2569 | ET4: เม.ย.2569 | EU4: พ.ค.2569 | EV4: มิ.ย.2569 | EW4: ก.ค.2569 | EX4: ส.ค.2569
B5: รวม | C5: =SUM(C6:C16) -> 41215 | D5: =SUM(D6:D16) -> 40067 | E5: =SUM(E6:E16) -> 36104 | F5: =SUM(F6:F16) -> 35337 | G5: =SUM(G6:G16) -> 27408 | H5: =SUM(H6:H16) -> 40947 | I5: =SUM(I6:I16) -> 37951 | J5: =SUM(J6:J16) -> 41154 | ... EX5: =SUM(EX6:EX16) -> 18828
A6: 1 | B6: ผู้บัญญัติกฎหมาย ข้าราชการระดับอาวุโส, ผู้จัดการ | C6: 612 | D6: 507 | E6: 699 | F6: 696 | G6: 575 | H6: 563 | I6: 678 | J6: 563 | K6: 757 | L6: 760 | M6: 738 | N6: 657 | O6: 584 | P6: 883 | Q6: 730 | R6: 431 | S6: 685 | T6: 1195 | U6: 902 | V6: 620 | W6: 615 | X6: 854 | Y6: 1127 | Z6: 895 | AA6: 869 | AB6: 963 | AC6: 893 | AD6: 769 | AE6: 953 | AF6: 1072 | AG6: 681 | AH6: 806 | AI6: 528 | AJ6: 742 | AK6: 805 | AL6: 501 | AM6: 580 | AN6: 794 | AO6: 577 | AP6: 500 | AQ6: 660 | AR6: 894 | AS6: 745 | AT6: 472 | AU6: 778 | AV6: 447 | AW6: 684 | AX6: 652 | AY6: 1028 | AZ6: 637 | BA6: 703 | BB6: 595 | BC6: 779 | BD6: 785 | BE6: 497 | BF6: 469 | BG6: 671 | BH6: 798 | BI6: 461 | BJ6: 571 | BK6: 409 | BL6: 1113 | BM6: 746 | BN6: 631 | BO6: 592 | BP6: 664 | BQ6: 613 | BR6: 672 | BS6: 347 | BT6: 454 | BU6: 468 | BV6: 578 | BW6: 284 | BX6: 813 | BY6: 513 | BZ6: 414 | CA6: 751 | CB6: 921 | CC6: 1339 | CD6: 1100 | CE6: 12284 | CF6: 480 | CG6: 1343 | CH6: 972 | CI6: 964 | CJ6: 1974 | CK6: 4017 | CL6: 1480 | CM6: 1407 | CN6: 1537 | CO6: 2158 | CP6: 2319 | CQ6: 1648 | CR6: 434 | CS6: 709 | CT6: 650 | CU6: 1332 | CV6: 1525 | CW6: 1654 | CX6: 903 | CY6: 1489 | CZ6: 1827 | DA6: 1003 | DB6: 1118 | DC6: 1369 | DD6: 619 | DE6: 1138 | DF6: 2357 | DG6: 3575 | DH6: 3062 | DI6: 2352 | DJ6: 971 | DK6: 6099 | DL6: 3138 | DM6: 839 | DN6: 1272 | DO6: 445 | DP6: 1134 | DQ6: 3242 | DR6: 2765 | DS6: 2919 | DT6: 3306 | DU6: 2474 | DV6: 1882 | DW6: 1789 | DX6: 4319 | DY6: 1143 | DZ6: 672 | EA6: 489 | EB6: 642 | EC6: 510 | ED6: 482 | EE6: 409 | EF6: 856 | EG6: 707 | EH6: 2434 | EI6: 4120 | EJ6: 810 | EK6: 421 | EL6: 602 | EM6: 384 | EN6: 457 | EO6: 2228 | EP6: 4275 | EQ6: 680 | ER6: 493 | ES6: 392 | ET6: 384 | EU6: 422 | EV6: 424 | EW6: 328 | EX6: 349
A7: 2 | B7: ผู้ประกอบวิชาชีพด้านต่าง ๆ | C7: 1455 | D7: 1479 | E7: 1905 | F7: 1935 | G7: 1343 | H7: 2463 | I7: 1654 | J7: 1661 | K7: 2229 | L7: 1211 | M7: 2371 | N7: 1483 | O7: 1602 | P7: 2196 | Q7: 1969 | R7: 1628 | S7: 1849 | T7: 2841 | U7: 2546 | V7: 1884 | W7: 1793 | X7: 1476 | Y7: 2049 | Z7: 1576 | AA7: 1703 | AB7: 2032 | AC7: 1609 | AD7: 2137 | AE7: 1617 | AF7: 1975 | AG7: 1496 | AH7: 1587 | AI7: 1204 | AJ7: 1165 | AK7: 1405 | AL7: 983 | AM7: 1177 | AN7: 1393 | AO7: 1936 | AP7: 1039 | AQ7: 1460 | AR7: 1949 | AS7: 1738 | AT7: 1556 | AU7: 1308 | AV7: 896 | AW7: 1046 | AX7: 923 | AY7: 1799 | AZ7: 1252 | BA7: 1491 | BB7: 978 | BC7: 1091 | BD7: 911 | BE7: 1169 | BF7: 1304 | BG7: 1242 | BH7: 700 | BI7: 940 | BJ7: 918 | BK7: 1078 | BL7: 1345 | BM7: 1227 | BN7: 1090 | BO7: 1163 | BP7: 1229 | BQ7: 1214 | BR7: 1304 | BS7: 670 | BT7: 684 | BU7: 816 | BV7: 846 | BW7: 914 | BX7: 968 | BY7: 498 | BZ7: 443 | CA7: 1132 | CB7: 982 | CC7: 1595 | CD7: 1061 | CE7: 15974 | CF7: 738 | CG7: 986 | CH7: 1196 | CI7: 1121 | CJ7: 1886 | CK7: 3897 | CL7: 1404 | CM7: 2870 | CN7: 2081 | CO7: 2470 | CP7: 3597 | CQ7: 2203 | CR7: 835 | CS7: 728 | CT7: 769 | CU7: 1359 | CV7: 1929 | CW7: 1310 | CX7: 1960 | CY7: 1592 | CZ7: 1254 | DA7: 1032 | DB7: 1397 | DC7: 2243 | DD7: 977 | DE7: 1647 | DF7: 2562 | DG7: 3289 | DH7: 4532 | DI7: 3471 | DJ7: 1375 | DK7: 7699 | DL7: 3106 | DM7: 945 | DN7: 1108 | DO7: 635 | DP7: 1144 | DQ7: 3161 | DR7: 2674 | DS7: 2416 | DT7: 3248 | DU7: 2815 | DV7: 3309 | DW7: 3639 | DX7: 6927 | DY7: 2478 | DZ7: 2805 | EA7: 1329 | EB7: 1326 | EC7: 1539 | ED7: 836 | EE7: 1040 | EF7: 1991 | EG7: 1476 | EH7: 2798 | EI7: 4264 | EJ7: 1789 | EK7: 1611 | EL7: 1718 | EM7: 1665 | EN7: 1024 | EO7: 4570 | EP7: 3296 | EQ7: 947 | ER7: 1185 | ES7: 1323 | ET7: 948 | EU7: 776 | EV7: 1226 | EW7: 848 | EX7: 732
A8: 3 | B8: ช่างเทคนิคและผู้ปฏิบัติงานที่เกี่ยวข้อง | C8: 3199 | D8: 4005 | E8: 4289 | F8: 3912 | G8: 3208 | H8: 4746 | I8: 4340 | J8: 5115 | K8: 5561 | L8: 3166 | M8: 4520 | N8: 4083 | O8: 4119 | P8: 5728 | Q8: 4248 | R8: 3892 | S8: 4447 | T8: 6078 | U8: 5479 | V8: 4165 | W8: 3886 | X8: 3480 | Y8: 6231 | Z8: 4632 | AA8: 4764 | AB8: 4661 | AC8: 4719 | AD8: 4010 | AE8: 4723 | AF8: 4117 | AG8: 3938 | AH8: 3851 | AI8: 3738 | AJ8: 2588 | AK8: 4004 | AL8: 3090 | AM8: 3421 | AN8: 4423 | AO8: 3989 | AP8: 3123 | AQ8: 3629 | AR8: 5099 | AS8: 4511 | AT8: 3194 | AU8: 3328 | AV8: 2568 | AW8: 3013 | AX8: 2846 | AY8: 6171 | AZ8: 3850 | BA8: 3554 | BB8: 3468 | BC8: 4609 | BD8: 3338 | BE8: 2768 | BF8: 3096 | BG8: 3644 | BH8: 2436 | BI8: 3102 | BJ8: 2817 | BK8: 3325 | BL8: 4317 | BM8: 6551 | BN8: 4593 | BO8: 4650 | BP8: 3535 | BQ8: 2749 | BR8: 3195 | BS8: 2082 | BT8: 1678 | BU8: 2069 | BV8: 2531 | BW8: 2249 | BX8: 2780 | BY8: 2090 | BZ8: 3672 | CA8: 5672 | CB8: 7818 | CC8: 7602 | CD8: 6646 | CE8: 48696 | CF8: 2779 | CG8: 4300 | CH8: 4349 | CI8: 5315 | CJ8: 7284 | CK8: 12969 | CL8: 6609 | CM8: 10913 | CN8: 6061 | CO8: 7571 | CP8: 9180 | CQ8: 12269 | CR8: 3029 | CS8: 3673 | CT8: 3606 | CU8: 4458 | CV8: 7237 | CW8: 8545 | CX8: 4722 | CY8: 5905 | CZ8: 5793 | DA8: 5367 | DB8: 5651 | DC8: 5374 | DD8: 4371 | DE8: 6509 | DF8: 11065 | DG8: 15113 | DH8: 20560 | DI8: 14454 | DJ8: 5575 | DK8: 18124 | DL8: 15193 | DM8: 5562 | DN8: 3978 | DO8: 2824 | DP8: 6681 | DQ8: 12585 | DR8: 11123 | DS8: 13384 | DT8: 15325 | DU8: 13058 | DV8: 12633 | DW8: 12148 | DX8: 23510 | DY8: 11342 | DZ8: 12026 | EA8: 7646 | EB8: 8147 | EC8: 6909 | ED8: 6467 | EE8: 5788 | EF8: 6996 | EG8: 7568 | EH8: 7246 | EI8: 14023 | EJ8: 7766 | EK8: 6480 | EL8: 6596 | EM8: 4114 | EN8: 5913 | EO8: 10840 | EP8: 8692 | EQ8: 5014 | ER8: 6680 | ES8: 6137 | ET8: 4457 | EU8: 3759 | EV8: 4354 | EW8: 4906 | EX8: 3324
A9: 4 | B9: เสมียน เจ้าหน้าที่ | C9: 16324 | D9: 14751 | E9: 5847 | F9: 5533 | G9: 4431 | H9: 7492 | I9: 6678 | J9: 5769 | K9: 8026 | L9: 4586 | M9: 6252 | N9: 5262 | O9: 5594 | P9: 7111 | Q9: 6257 | R9: 5481 | S9: 6479 | T9: 8254 | U9: 7250 | V9: 6170 | W9: 5559 | X9: 4739 | Y9: 7553 | Z9: 5567 | AA9: 6749 | AB9: 6935 | AC9: 6170 | AD9: 5833 | AE9: 5780 | AF9: 5685 | AG9: 4232 | AH9: 4472 | AI9: 4182 | AJ9: 3177 | AK9: 5374 | AL9: 4553 | AM9: 4819 | AN9: 5517 | AO9: 6654 | AP9: 8007 | AQ9: 5440 | AR9: 7228 | AS9: 5872 | AT9: 4997 | AU9: 4818 | AV9: 3463 | AW9: 4715 | AX9: 4028 | AY9: 6688 | AZ9: 4878 | BA9: 4490 | BB9: 4933 | BC9: 5599 | BD9: 4735 | BE9: 3872 | BF9: 3818 | BG9: 3723 | BH9: 3817 | BI9: 4611 | BJ9: 4207 | BK9: 4059 | BL9: 5721 | BM9: 6697 | BN9: 6304 | BO9: 6021 | BP9: 5290 | BQ9: 4020 | BR9: 5906 | BS9: 3102 | BT9: 2853 | BU9: 3090 | BV9: 3414 | BW9: 3142 | BX9: 3323 | BY9: 2951 | BZ9: 3462 | CA9: 4031 | CB9: 4762 | CC9: 4974 | CD9: 5603 | CE9: 28575 | CF9: 2090 | CG9: 3085 | CH9: 4670 | CI9: 3183 | CJ9: 4251 | CK9: 7230 | CL9: 3828 | CM9: 4513 | CN9: 4726 | CO9: 3902 | CP9: 6412 | CQ9: 6638 | CR9: 2273 | CS9: 3005 | CT9: 2649 | CU9: 2511 | CV9: 4939 | CW9: 5177 | CX9: 3633 | CY9: 6362 | CZ9: 4983 | DA9: 4057 | DB9: 5904 | DC9: 5413 | DD9: 2435 | DE9: 4908 | DF9: 7717 | DG9: 10211 | DH9: 11038 | DI9: 8772 | DJ9: 3515 | DK9: 10487 | DL9: 8177 | DM9: 4733 | DN9: 2354 | DO9: 1553 | DP9: 4390 | DQ9: 8669 | DR9: 7823 | DS9: 8671 | DT9: 9852 | DU9: 12058 | DV9: 9292 | DW9: 9092 | DX9: 17580 | DY9: 8528 | DZ9: 7540 | EA9: 5556 | EB9: 5292 | EC9: 6583 | ED9: 4719 | EE9: 4909 | EF9: 4566 | EG9: 6364 | EH9: 7853 | EI9: 12296 | EJ9: 5068 | EK9: 4270 | EL9: 3642 | EM9: 2447 | EN9: 4603 | EO9: 8305 | EP9: 5971 | EQ9: 3798 | ER9: 4454 | ES9: 3353 | ET9: 3489 | EU9: 2890 | EV9: 3198 | EW9: 3350 | EX9: 2197
A10: 5 | B10: พนักงานบริการ พนักงานขายในร้านค้าและตลาด | C10: 5259 | D10: 5835 | E10: 7017 | F10: 5767 | G10: 5568 | H10: 7129 | I10: 7329 | J10: 6744 | K10: 8326 | L10: 5371 | M10: 7276 | N10: 6442 | O10: 6839 | P10: 7993 | Q10: 7496 | R10: 6482 | S10: 7830 | T10: 9496 | U10: 8106 | V10: 6684 | W10: 7029 | X10: 5655 | Y10: 7884 | Z10: 6829 | AA10: 7187 | AB10: 7425 | AC10: 7142 | AD10: 7244 | AE10: 7293 | AF10: 7519 | AG10: 5397 | AH10: 6306 | AI10: 5046 | AJ10: 4744 | AK10: 6349 | AL10: 5492 | AM10: 5784 | AN10: 6333 | AO10: 6782 | AP10: 5056 | AQ10: 6697 | AR10: 9052 | AS10: 7491 | AT10: 6644 | AU10: 6436 | AV10: 4232 | AW10: 5028 | AX10: 5395 | AY10: 8064 | AZ10: 6427 | BA10: 6591 | BB10: 6886 | BC10: 6066 | BD10: 4782 | BE10: 4837 | BF10: 5071 | BG10: 5638 | BH10: 3823 | BI10: 4761 | BJ10: 5845 | BK10: 5431 | BL10: 6397 | BM10: 7863 | BN10: 7187 | BO10: 6844 | BP10: 6498 | BQ10: 4808 | BR10: 5641 | BS10: 3411 | BT10: 3565 | BU10: 4092 | BV10: 4657 | BW10: 3801 | BX10: 4104 | BY10: 3471 | BZ10: 23063 | CA10: 3437 | CB10: 4429 | CC10: 5151 | CD10: 4070 | CE10: 49331 | CF10: 1492 | CG10: 4965 | CH10: 3905 | CI10: 2582 | CJ10: 3015 | CK10: 7259 | CL10: 4525 | CM10: 5688 | CN10: 2923 | CO10: 3319 | CP10: 4670 | CQ10: 6883 | CR10: 2219 | CS10: 2567 | CT10: 3315 | CU10: 4196 | CV10: 4264 | CW10: 6182 | CX10: 3741 | CY10: 4518 | CZ10: 4704 | DA10: 4793 | DB10: 3886 | DC10: 6145 | DD10: 2302 | DE10: 3961 | DF10: 9376 | DG10: 11055 | DH10: 14524 | DI10: 10153 | DJ10: 3728 | DK10: 12393 | DL10: 9074 | DM10: 3002 | DN10: 1981 | DO10: 2013 | DP10: 3591 | DQ10: 8927 | DR10: 7556 | DS10: 11202 | DT10: 11006 | DU10: 10337 | DV10: 11169 | DW10: 10135 | DX10: 17565 | DY10: 8384 | DZ10: 8336 | EA10: 4765 | EB10: 11888 | EC10: 6248 | ED10: 5381 | EE10: 5898 | EF10: 5475 | EG10: 7318 | EH10: 7633 | EI10: 9426 | EJ10: 5518 | EK10: 4129 | EL10: 4209 | EM10: 2809 | EN10: 3840 | EO10: 6985 | EP10: 9498 | EQ10: 4987 | ER10: 4854 | ES10: 4019 | ET10: 3570 | EU10: 2992 | EV10: 4517 | EW10: 3110 | EX10: 2733
A11: 6 | B11: ผู้ปฏิบัติงานฝีมือด้านการเกษตรและประมง (แปรรูปขั้นพื้นฐาน) | C11: 227 | D11: 64 | E11: 110 | F11: 92 | G11: 72 | H11: 211 | I11: 75 | J11: 53 | K11: 72 | L11: 94 | M11: 94 | N11: 258 | O11: 94 | P11: 164 | Q11: 116 | R11: 217 | S11: 105 | T11: 75 | U11: 94 | V11: 39 | W11: 99 | X11: 92 | Y11: 252 | Z11: 96 | AA11: 128 | AB11: 175 | AC11: 72 | AD11: 84 | AE11: 155 | AF11: 114 | AG11: 62 | AH11: 46 | AI11: 135 | AJ11: 27 | AK11: 104 | AL11: 52 | AM11: 115 | AN11: 72 | AO11: 96 | AP11: 97 | AQ11: 85 | AR11: 157 | AS11: 107 | AT11: 95 | AU11: 209 | AV11: 67 | AW11: 152 | AX11: 102 | AY11: 133 | AZ11: 88 | BA11: 83 | BB11: 108 | BC11: 74 | BD11: 107 | BE11: 67 | BF11: 107 | BG11: 130 | BH11: 121 | BI11: 71 | BJ11: 70 | BK11: 71 | BL11: 106 | BM11: 72 | BN11: 43 | BO11: 104 | BP11: 71 | BQ11: 34 | BR11: 209 | BS11: 32 | BT11: 40 | BU11: 108 | BV11: 54 | BW11: 23 | BX11: 72 | BY11: 29 | BZ11: 69 | CA11: 109 | CB11: 35 | CC11: 31 | CD11: 69 | CE11: 3629 | CF11: 87 | CG11: 404 | CH11: 175 | CI11: 99 | CJ11: 96 | CK11: 242 | CL11: 182 | CM11: 386 | CN11: 92 | CO11: 172 | CP11: 47 | CQ11: 681 | CR11: 37 | CS11: 13 | CT11: 96 | CU11: 195 | CV11: 87 | CW11: 143 | CX11: 63 | CY11: 107 | CZ11: 85 | DA11: 101 | DB11: 45 | DC11: 71 | DD11: 37 | DE11: 220 | DF11: 229 | DG11: 326 | DH11: 324 | DI11: 446 | DJ11: 41 | DK11: 126 | DL11: 387 | DM11: 28 | DN11: 55 | DO11: 22 | DP11: 65 | DQ11: 541 | DR11: 321 | DS11: 367 | DT11: 174 | DU11: 156 | DV11: 154 | DW11: 266 | DX11: 1118 | DY11: 616 | DZ11: 271 | EA11: 80 | EB11: 18 | EC11: 256 | ED11: 91 | EE11: 61 | EF11: 54 | EG11: 143 | EH11: 83 | EI11: 1085 | EJ11: 95 | EK11: 14 | EL11: 55 | EM11: 89 | EN11: 47 | EO11: 62 | EP11: 206 | EQ11: 114 | ER11: 63 | ES11: 50 | ET11: 24 | EU11: 47 | EV11: 58 | EW11: 41 | EX11: 22
A12: 7 | B12: ผู้ปฏิบัติงานโดยใช้ฝีมือในธุรกิจต่าง ๆ | C12: 2706 | D12: 2585 | E12: 2245 | F12: 2272 | G12: 2280 | H12: 3254 | I12: 3060 | J12: 2383 | K12: 3067 | L12: 1862 | M12: 3233 | N12: 1998 | O12: 2089 | P12: 3244 | Q12: 2183 | R12: 2177 | S12: 2212 | T12: 3630 | U12: 3174 | V12: 2615 | W12: 2263 | X12: 2058 | Y12: 2874 | Z12: 2846 | AA12: 2753 | AB12: 3433 | AC12: 2648 | AD12: 2291 | AE12: 2396 | AF12: 2352 | AG12: 2237 | AH12: 2408 | AI12: 2115 | AJ12: 1265 | AK12: 2198 | AL12: 1704 | AM12: 2271 | AN12: 1879 | AO12: 2149 | AP12: 2136 | AQ12: 2345 | AR12: 2732 | AS12: 2979 | AT12: 1890 | AU12: 1933 | AV12: 1619 | AW12: 1616 | AX12: 1566 | AY12: 3633 | AZ12: 1864 | BA12: 1966 | BB12: 1864 | BC12: 1600 | BD12: 1789 | BE12: 1727 | BF12: 1710 | BG12: 2081 | BH12: 1467 | BI12: 1770 | BJ12: 1327 | BK12: 1631 | BL12: 2126 | BM12: 2400 | BN12: 1453 | BO12: 2412 | BP12: 1702 | BQ12: 1172 | BR12: 1418 | BS12: 1092 | BT12: 1118 | BU12: 1825 | BV12: 1065 | BW12: 1310 | BX12: 1638 | BY12: 1007 | BZ12: 2294 | CA12: 3070 | CB12: 4784 | CC12: 5212 | CD12: 2658 | CE12: 29583 | CF12: 781 | CG12: 1294 | CH12: 1756 | CI12: 1120 | CJ12: 1898 | CK12: 4347 | CL12: 1985 | CM12: 2938 | CN12: 2610 | CO12: 2628 | CP12: 2982 | CQ12: 3563 | CR12: 1136 | CS12: 2086 | CT12: 1893 | CU12: 2738 | CV12: 3935 | CW12: 3936 | CX12: 2172 | CY12: 2701 | CZ12: 1603 | DA12: 1943 | DB12: 1663 | DC12: 2569 | DD12: 2812 | DE12: 2433 | DF12: 6424 | DG12: 5755 | DH12: 8151 | DI12: 6484 | DJ12: 2356 | DK12: 4599 | DL12: 4212 | DM12: 2754 | DN12: 792 | DO12: 867 | DP12: 2649 | DQ12: 4281 | DR12: 4124 | DS12: 3284 | DT12: 4749 | DU12: 3602 | DV12: 4375 | DW12: 3577 | DX12: 6315 | DY12: 3670 | DZ12: 3509 | EA12: 2416 | EB12: 1723 | EC12: 1838 | ED12: 1240 | EE12: 1473 | EF12: 1790 | EG12: 2490 | EH12: 1498 | EI12: 2158 | EJ12: 2188 | EK12: 1315 | EL12: 1512 | EM12: 1540 | EN12: 1746 | EO12: 2695 | EP12: 1541 | EQ12: 1439 | ER12: 1333 | ES12: 2031 | ET12: 1203 | EU12: 1437 | EV12: 1280 | EW12: 974 | EX12: 826
A13: 8 | B13: ผู้ปฏิบัติงานในโรงงาน ผู้ควบคุมเครื่องจักรและผู้ปฏิบัติงานด้านการประกอบ | C13: 2773 | D13: 2181 | E13: 2738 | F13: 3094 | G13: 1968 | H13: 2145 | I13: 3118 | J13: 2949 | K13: 3324 | L13: 1790 | M13: 2378 | N13: 2870 | O13: 3173 | P13: 2552 | Q13: 2632 | R13: 1840 | S13: 1975 | T13: 4318 | U13: 3685 | V13: 2813 | W13: 3328 | X13: 1979 | Y13: 2871 | Z13: 2888 | AA13: 3492 | AB13: 2930 | AC13: 2947 | AD13: 2544 | AE13: 2244 | AF13: 1950 | AG13: 1977 | AH13: 1469 | AI13: 2242 | AJ13: 1749 | AK13: 2009 | AL13: 1975 | AM13: 1690 | AN13: 2227 | AO13: 2259 | AP13: 1809 | AQ13: 2179 | AR13: 2530 | AS13: 2602 | AT13: 1549 | AU13: 1748 | AV13: 10195 | AW13: 1371 | AX13: 1885 | AY13: 3016 | AZ13: 1971 | BA13: 1558 | BB13: 1467 | BC13: 1716 | BD13: 2333 | BE13: 1297 | BF13: 1827 | BG13: 1451 | BH13: 1329 | BI13: 1534 | BJ13: 1602 | BK13: 2292 | BL13: 2084 | BM13: 2561 | BN13: 1748 | BO13: 1967 | BP13: 1533 | BQ13: 1289 | BR13: 1827 | BS13: 841 | BT13: 1001 | BU13: 1205 | BV13: 1254 | BW13: 1231 | BX13: 1484 | BY13: 850 | BZ13: 1318 | CA13: 1166 | CB13: 1925 | CC13: 1500 | CD13: 2191 | CE13: 17757 | CF13: 930 | CG13: 1090 | CH13: 1362 | CI13: 1226 | CJ13: 1783 | CK13: 4222 | CL13: 1622 | CM13: 1789 | CN13: 2540 | CO13: 1505 | CP13: 2528 | CQ13: 2831 | CR13: 1011 | CS13: 1173 | CT13: 1415 | CU13: 1646 | CV13: 1986 | CW13: 4320 | CX13: 2361 | CY13: 2089 | CZ13: 2347 | DA13: 2107 | DB13: 1652 | DC13: 1821 | DD13: 1545 | DE13: 2676 | DF13: 4532 | DG13: 6011 | DH13: 8866 | DI13: 4984 | DJ13: 3866 | DK13: 3405 | DL13: 3471 | DM13: 1989 | DN13: 1185 | DO13: 802 | DP13: 2483 | DQ13: 4675 | DR13: 3242 | DS13: 4141 | DT13: 5390 | DU13: 3940 | DV13: 3388 | DW13: 4367 | DX13: 7742 | DY13: 4973 | DZ13: 4494 | EA13: 3339 | EB13: 2748 | EC13: 2408 | ED13: 2191 | EE13: 2433 | EF13: 1866 | EG13: 2772 | EH13: 3092 | EI13: 2833 | EJ13: 1980 | EK13: 1272 | EL13: 1322 | EM13: 1215 | EN13: 1755 | EO13: 3306 | EP13: 2745 | EQ13: 1120 | ER13: 1183 | ES13: 1394 | ET13: 1099 | EU13: 1023 | EV13: 1011 | EW13: 1251 | EX13: 848
A14: 9 | B14: อาชีพงานพื้นฐาน | C14: 8652 | D14: 8643 | E14: 11228 | F14: 11946 | G14: 7963 | H14: 12929 | I14: 11008 | J14: 15915 | K14: 20302 | L14: 9875 | M14: 12034 | N14: 10426 | O14: 9952 | P14: 12645 | Q14: 12425 | R14: 11971 | S14: 10997 | T14: 15393 | U14: 18524 | V14: 11625 | W14: 13752 | X14: 11311 | Y14: 12507 | Z14: 14791 | AA14: 12231 | AB14: 14439 | AC14: 15348 | AD14: 16189 | AE14: 13624 | AF14: 11906 | AG14: 13079 | AH14: 12017 | AI14: 10879 | AJ14: 7191 | AK14: 10457 | AL14: 9943 | AM14: 10771 | AN14: 11249 | AO14: 12981 | AP14: 12389 | AQ14: 14846 | AR14: 14340 | AS14: 11924 | AT14: 10877 | AU14: 9797 | AV14: 7790 | AW14: 9745 | AX14: 7992 | AY14: 13238 | AZ14: 10038 | BA14: 8971 | BB14: 9704 | BC14: 11815 | BD14: 8695 | BE14: 7167 | BF14: 8614 | BG14: 10429 | BH14: 5909 | BI14: 7590 | BJ14: 7549 | BK14: 9792 | BL14: 12059 | BM14: 14964 | BN14: 13503 | BO14: 10983 | BP14: 9491 | BQ14: 8409 | BR14: 10288 | BS14: 6027 | BT14: 6958 | BU14: 7551 | BV14: 7567 | BW14: 8139 | BX14: 7782 | BY14: 7366 | BZ14: 7524 | CA14: 9118 | CB14: 11901 | CC14: 12776 | CD14: 14408 | CE14: 255813 | CF14: 7047 | CG14: 15486 | CH14: 14509 | CI14: 13565 | CJ14: 16976 | CK14: 35956 | CL14: 11840 | CM14: 13971 | CN14: 17890 | CO14: 16607 | CP14: 28381 | CQ14: 76308 | CR14: 11883 | CS14: 18084 | CT14: 12968 | CU14: 15365 | CV14: 17740 | CW14: 25270 | CX14: 13458 | CY14: 20209 | CZ14: 18497 | DA14: 15075 | DB14: 15919 | DC14: 14703 | DD14: 10236 | DE14: 15337 | DF14: 42013 | DG14: 37258 | DH14: 50461 | DI14: 34819 | DJ14: 11478 | DK14: 26490 | DL14: 28708 | DM14: 9465 | DN14: 6589 | DO14: 6219 | DP14: 15676 | DQ14: 28251 | DR14: 27494 | DS14: 30227 | DT14: 34373 | DU14: 33238 | DV14: 29200 | DW14: 31377 | DX14: 40185 | DY14: 36608 | DZ14: 27215 | EA14: 21217 | EB14: 15374 | EC14: 12191 | ED14: =104+15110 -> 15214 | EE14: 16643 | EF14: 15371 | EG14: 15822 | EH14: 13573 | EI14: 15375 | EJ14: =215+14532 -> 14747 | EK14: =63+14328 -> 14391 | EL14: =107+11811 -> 11918 | EM14: =90+8316 -> 8406 | EN14: =77+11915 -> 11992 | EO14: =43+13872 -> 13915 | EP14: =79+14888 -> 14967 | EQ14: 13073 | ER14: 12942 | ES14: =107+14232 -> 14339 | ET14: =34+12061 -> 12095 | EU14: =32+12168 -> 12200 | EV14: =60+10169 -> 10229 | EW14: 8832 | EX14: 7797
A15: T | B15: ผู้ฝึกงาน | C15: 8 | D15: 17 | E15: 26 | F15: 90 | G15: 0 | H15: 15 | I15: 11 | J15: 2 | K15: 39 | L15: 20 | M15: 38 | N15: 28 | O15: 36 | P15: 14 | Q15: 47 | R15: 29 | S15: 14 | T15: 34 | U15: 33 | V15: 11 | W15: 30 | X15: 10 | Y15: 45 | Z15: 62 | AA15: 18 | AB15: 26 | AC15: 40 | AD15: 16 | AE15: 21 | AF15: 98 | AG15: 5 | AH15: 14 | AI15: 21 | AJ15: 0 | AK15: 23 | AL15: 11 | AM15: 17 | AN15: 2 | AO15: 68 | AP15: 35 | AQ15: 7 | AR15: 10 | AS15: 16 | AT15: 3 | AU15: 1 | AV15: 60 | AW15: 2 | AX15: 0 | AY15: 79 | AZ15: 188 | BA15: 219 | BB15: 93 | BC15: 79 | BD15: 21 | BE15: 1 | BF15: 11 | BG15: 24 | BH15: 29 | BI15: 0 | BJ15: 8 | BK15: 25 | BL15: 257 | BM15: 487 | BN15: 40 | BO15: 81 | BP15: 34 | BQ15: 3 | BR15: 50 | BS15: 10 | BT15: 0 | BU15: 0 | BV15: 13 | BW15: 1 | BX15: 2 | BZ15: 1 | CA15: 3 | CB15: 1 | CC15: 2 | CD15: 20 | CG15: 5 | CU15: 5 | CY15: 5 | EQ15: 0
A16: X | B16: ผู้ปฏิบัติงานซึ่งมิอาจจัดประเภท | AA16: 0 | AB16: 0 | AC16: 0 | AD16: 0 | AE16: 0 | AF16: 0 | AG16: 0 | AH16: 0 | AI16: 0 | AJ16: 0 | AK16: 0 | AL16: 0 | AM16: 0 | AN16: 0 | AO16: 0 | AP16: 0 | AQ16: 0 | AR16: 0 | AS16: 0 | AT16: 0 | AU16: 0 | AV16: 0 | AW16: 0 | AX16: 0 | AY16: 0 | AZ16: 0 | BA16: 0 | BB16: 0 | BC16: 0 | BD16: 0 | BE16: 0 | BF16: 0 | BG16: 0 | BH16: 0 | BI16: 0 | BJ16: 0 | BK16: 0 | BL16: 0 | BM16: 0 | BN16: 0 | BO16: 0 | BP16: 0 | BQ16: 0 | BR16: 0 | BS16: 0 | BT16: 0 | BU16: 0 | BV16: 0 | BW16: 0 | BX16: 0 | BY16: 0 | BZ16: 0 | CA16: 0 | CC16: 1
A18: ที่มา : กรมการจัดหางาน
A19: รวบรวมโดย : กองบริหารข้อมูลตลาดแรงงาน
A20: หมายเหตุ : 1. เป็นข้อมูลผู้สมัครงานที่มาใช้บริการจัดหางานกับกรมการจัดหางานเท่านั้น
A21: 2. ข้อมูลจากระบบสารสนเทศการจัดหางานในประเทศ กรมการจัดหางาน

Sheet CSV
A1: จำนวนตำแหน่งงานจำแนกตามประเภทอาชีพ
A2: Year | B2: Month | C2: Total | D2: 1 | E2: 2 | F2: 3 | G2: 4 | H2: 5 | I2: 6 | J2: 7 | K2: 8 | L2: 9 | M2: T | N2: X
A3: 2014 | B3: Jan | C3: =SUM(D3:N3) -> 41215 | D3: 612 | E3: 1455 | F3: 3199 | G3: 16324 | H3: 5259 | I3: 227 | J3: 2706 | K3: 2773 | L3: 8652 | M3: 8
A4: 2014 | B4: Feb | C4: =SUM(D4:N4) -> 40067 | D4: 507 | E4: 1479 | F4: 4005 | G4: 14751 | H4: 5835 | I4: 64 | J4: 2585 | K4: 2181 | L4: 8643 | M4: 17
A5: 2014 | B5: Mar | C5: =SUM(D5:N5) -> 36104 | D5: 699 | E5: 1905 | F5: 4289 | G5: 5847 | H5: 7017 | I5: 110 | J5: 2245 | K5: 2738 | L5: 11228 | M5: 26
A6: 2014 | B6: Apr | C6: =SUM(D6:N6) -> 35337 | D6: 696 | E6: 1935 | F6: 3912 | G6: 5533 | H6: 5767 | I6: 92 | J6: 2272 | K6: 3094 | L6: 11946 | M6: 90
A7: 2014 | B7: May | C7: =SUM(D7:N7) -> 27408 | D7: 575 | E7: 1343 | F7: 3208 | G7: 4431 | H7: 5568 | I7: 72 | J7: 2280 | K7: 1968 | L7: 7963 | M7: 0
A8: 2014 | B8: Jun | C8: =SUM(D8:N8) -> 40947 | D8: 563 | E8: 2463 | F8: 4746 | G8: 7492 | H8: 7129 | I8: 211 | J8: 3254 | K8: 2145 | L8: 12929 | M8: 15
A9: 2014 | B9: Jul | C9: =SUM(D9:N9) -> 37951 | D9: 678 | E9: 1654 | F9: 4340 | G9: 6678 | H9: 7329 | I9: 75 | J9: 3060 | K9: 3118 | L9: 11008 | M9: 11
A10: 2014 | B10: Aug | C10: =SUM(D10:N10) -> 41154 | D10: 563 | E10: 1661 | F10: 5115 | G10: 5769 | H10: 6744 | I10: 53 | J10: 2383 | K10: 2949 | L10: 15915 | M10: 2
A11: 2014 | B11: Sep | C11: =SUM(D11:N11) -> 51703 | D11: 757 | E11: 2229 | F11: 5561 | G11: 8026 | H11: 8326 | I11: 72 | J11: 3067 | K11: 3324 | L11: 20302 | M11: 39
A12: 2014 | B12: Oct | C12: =SUM(D12:N12) -> 28735 | D12: 760 | E12: 1211 | F12: 3166 | G12: 4586 | H12: 5371 | I12: 94 | J12: 1862 | K12: 1790 | L12: 9875 | M12: 20
A13: 2014 | B13: Nov | C13: =SUM(D13:N13) -> 38934 | D13: 738 | E13: 2371 | F13: 4520 | G13: 6252 | H13: 7276 | I13: 94 | J13: 3233 | K13: 2378 | L13: 12034 | M13: 38
A14: 2014 | B14: Dec | C14: =SUM(D14:N14) -> 33507 | D14: 657 | E14: 1483 | F14: 4083 | G14: 5262 | H14: 6442 | I14: 258 | J14: 1998 | K14: 2870 | L14: 10426 | M14: 28
... A26: 2015 | B26: Dec | C26: =SUM(D26:N26) -> 40182 | D26: 895 | E26: 1576 | F26: 4632 | G26: 5567 | H26: 6829 | I26: 96 | J26: 2846 | K26: 2888 | L26: 14791 | M26: 62
A27: 2016 | B27: Jan | C27: =SUM(D27:N27) -> 39894 | D27: 869 | E27: 1703 | F27: 4764 | G27: 6749 | H27: 7187 | I27: 128 | J27: 2753 | K27: 3492 | L27: 12231 | M27: 18 | N27: 0
A28: 2016 | B28: Feb | C28: =SUM(D28:N28) -> 43019 | D28: 963 | E28: 2032 | F28: 4661 | G28: 6935 | H28: 7425 | I28: 175 | J28: 3433 | K28: 2930 | L28: 14439 | M28: 26 | N28: 0
A29: 2016 | B29: Mar | C29: =SUM(D29:N29) -> 41588 | D29: 893 | E29: 1609 | F29: 4719 | G29: 6170 | H29: 7142 | I29: 72 | J29: 2648 | K29: 2947 | L29: 15348 | M29: 40 | N29: 0
A30: 2016 | B30: Apr | C30: =SUM(D30:N30) -> 41117 | D30: 769 | E30: 2137 | F30: 4010 | G30: 5833 | H30: 7244 | I30: 84 | J30: 2291 | K30: 2544 | L30: 16189 | M30: 16 | N30: 0
A31: 2016 | B31: May | C31: =SUM(D31:N31) -> 38806 | D31: 953 | E31: 1617 | F31: 4723 | G31: 5780 | H31: 7293 | I31: 155 | J31: 2396 | K31: 2244 | L31: 13624 | M31: 21 | N31: 0
A32: 2016 | B32: Jun | C32: =SUM(D32:N32) -> 36788 | D32: 1072 | E32: 1975 | F32: 4117 | G32: 5685 | H32: 7519 | I32: 114 | J32: 2352 | K32: 1950 | L32: 11906 | M32: 98 | N32: 0
A33: 2016 | B33: Jul | C33: =SUM(D33:N33) -> 33104 | D33: 681 | E33: 1496 | F33: 3938 | G33: 4232 | H33: 5397 | I33: 62 | J33: 2237 | K33: 1977 | L33: 13079 | M33: 5 | N33: 0
A34: 2016 | B34: Aug | C34: =SUM(D34:N34) -> 32976 | D34: 806 | E34: 1587 | F34: 3851 | G34: 4472 | H34: 6306 | I34: 46 | J34: 2408 | K34: 1469 | L34: 12017 | M34: 14 | N34: 0
A35: 2016 | B35: Sep | C35: =SUM(D35:N35) -> 30090 | D35: 528 | E35: 1204 | F35: 3738 | G35: 4182 | H35: 5046 | I35: 135 | J35: 2115 | K35: 2242 | L35: 10879 | M35: 21 | N35: 0
A36: 2016 | B36: Oct | C36: =SUM(D36:N36) -> 22648 | D36: 742 | E36: 1165 | F36: 2588 | G36: 3177 | H36: 4744 | I36: 27 | J36: 1265 | K36: 1749 | L36: 7191 | M36: 0 | N36: 0
A37: 2016 | B37: Nov | C37: =SUM(D37:N37) -> 32728 | D37: 805 | E37: 1405 | F37: 4004 | G37: 5374 | H37: 6349 | I37: 104 | J37: 2198 | K37: 2009 | L37: 10457 | M37: 23 | N37: 0
A38: 2016 | B38: Dec | C38: =SUM(D38:N38) -> 28304 | D38: 501 | E38: 983 | F38: 3090 | G38: 4553 | H38: 5492 | I38: 52 | J38: 1704 | K38: 1975 | L38: 9943 | M38: 11 | N38: 0
... A76: 2020 | B76: Feb | C76: =SUM(D76:N76) -> 22966 | D76: 813 | E76: 968 | F76: 2780 | G76: 3323 | H76: 4104 | I76: 72 | J76: 1638 | K76: 1484 | L76: 7782 | M76: 2 | N76: 0
A77: 2020 | B77: Mar | C77: =SUM(D77:N77) -> 18775 | D77: 513 | E77: 498 | F77: 2090 | G77: 2951 | H77: 3471 | I77: 29 | J77: 1007 | K77: 850 | L77: 7366 | N77: 0
A78: 2020 | B78: Apr | C78: =SUM(D78:N78) -> 42260 | D78: 414 | E78: 443 | F78: 3672 | G78: 3462 | H78: 23063 | I78: 69 | J78: 2294 | K78: 1318 | L78: 7524 | M78: 1 | N78: 0
A79: 2020 | B79: May | C79: =SUM(D79:N79) -> 28489 | D79: 751 | E79: 1132 | F79: 5672 | G79: 4031 | H79: 3437 | I79: 109 | J79: 3070 | K79: 1166 | L79: 9118 | M79: 3 | N79: 0
A80: 2020 | B80: Jun | C80: =SUM(D80:N80) -> 37558 | D80: 921 | E80: 982 | F80: 7818 | G80: 4762 | H80: 4429 | I80: 35 | J80: 4784 | K80: 1925 | L80: 11901 | M80: 1
A81: 2020 | B81: Jul | C81: =SUM(D81:N81) -> 40183 | D81: 1339 | E81: 1595 | F81: 7602 | G81: 4974 | H81: 5151 | I81: 31 | J81: 5212 | K81: 1500 | L81: 12776 | M81: 2 | N81: 1
A82: 2020 | B82: Aug | C82: =SUM(D82:N82) -> 37826 | D82: 1100 | E82: 1061 | F82: 6646 | G82: 5603 | H82: 4070 | I82: 69 | J82: 2658 | K82: 2191 | L82: 14408 | M82: 20
A83: 2020 | B83: Sep | C83: =SUM(D83:N83) -> 461642 | D83: 12284 | E83: 15974 | F83: 48696 | G83: 28575 | H83: 49331 | I83: 3629 | J83: 29583 | K83: 17757 | L83: 255813
A84: 2020 | B84: Oct | C84: =SUM(D84:N84) -> 16424 | D84: 480 | E84: 738 | F84: 2779 | G84: 2090 | H84: 1492 | I84: 87 | J84: 781 | K84: 930 | L84: 7047
A85: 2020 | B85: Nov | C85: =SUM(D85:N85) -> 32958 | D85: 1343 | E85: 986 | F85: 4300 | G85: 3085 | H85: 4965 | I85: 404 | J85: 1294 | K85: 1090 | L85: 15486 | M85: 5
A86: 2020 | B86: Dec | C86: =SUM(D86:N86) -> 32894 | D86: 972 | E86: 1196 | F86: 4349 | G86: 4670 | H86: 3905 | I86: 175 | J86: 1756 | K86: 1362 | L86: 14509
A87: 2021 | B87: Jan | C87: =SUM(D87:N87) -> 29175 | D87: 964 | E87: 1121 | F87: 5315 | G87: 3183 | H87: 2582 | I87: 99 | J87: 1120 | K87: 1226 | L87: 13565
A88: 2021 | B88: Feb | C88: =SUM(D88:N88) -> 39163 | D88: 1974 | E88: 1886 | F88: 7284 | G88: 4251 | H88: 3015 | I88: 96 | J88: 1898 | K88: 1783 | L88: 16976
...

Sheet Data Dic
A1: จำนวนตำแหน่งงานจำแนกตามประเภทอาชีพ
A2: ลำดับที่ | B2: ชื่อคอลัมภ์ | C2: ชนิดข้อมูล | D2: รายละเอียด
A3: 1 | B3: Year | C3: timestamp | D3: ปี ค.ศ.
A4: 2 | B4: Month | C4: timestamp | D4: เดือน
A5: 3 | B5: 1 | C5: numeric | D5: ผู้ปฏิบัติกฎหมาย ข้าราชการระดับอาวุโส ผู้จัดการ
A6: 4 | B6: 2 | C6: numeric | D6: ผู้ประกอบวิชาชีพต่าง ๆ
A7: 5 | B7: 3 | C7: numeric | D7: ช่างเทคนิคและผู้ปฏิบัติงานที่เกี่ยวข้อง
A8: 6 | B8: 4 | C8: numeric | D8: เสมียน เจ้าหน้าที่
A9: 7 | B9: 5 | C9: numeric | D9: พนักงานบริการ พนักงานขายในร้านค้าและตลาด
A10: 8 | B10: 6 | C10: numeric | D10: ผู้ปฏิบัติงานฝีมือด้านการเกษตร และประมง (แปรรูปขั้นพื้นฐาน)
A11: 9 | B11: 7 | C11: numeric | D11: ผู้ปฏิบัติงานโดยใช้ฝีมือในธุรกิจต่าง ๆ
A12: 10 | B12: 8 | C12: numeric | D12: ผู้ปฏิบัติงานในโรงงาน ผู้ควบคุมเรื่องจักรและผู้ปฏิบัติงานด้านการประกอบ
A13: 11 | B13: 9 | C13: numeric | D13: อาชีพงานพื้นฐาน
A14: 12 | B14: T | C14: numeric | D14: ผู้ฝึกงาน
A15: 13 | B15: X | C15: numeric | D15: ผู้ปฏิบัติงานซึ่งมิอาจจัดประเภท
A16: 14 | B16: 0 | C16: numeric | D16: ทหาร
